<?xml version="1.0" ?>
<robot name="iCub" version="1.0">
  <link name="iCub"/>
  <joint name="base_footprint_joint" type="fixed">
    <origin xyz="0.0 0.0 0.0" rpy="0.0 0.0 0.0"/>
    <parent link="iCub"/>
    <child link="base_footprint"/>
  </joint>
  <link name="base_footprint">
    <inertial>
      <origin xyz="0.0 0.0 0.0" rpy="0.0 0.0 0.0"/>
      <mass value="1.0"/>
      <inertia ixx="0.009999999776482582" ixy="0.0" ixz="0.0" iyy="0.009999999776482582" iyz="0.0" izz="0.009999999776482582"/>
    </inertial>
    <visual name="SM_base_footprint_visual_0">
      <origin xyz="0.0 0.0 0.0" rpy="0.0 0.0 0.0"/>
      <geometry>
        <box size="0.009999999776482582 0.009999999776482582 0.009999999776482582"/>
      </geometry>
      <material name="SM_base_footprint_visual_0_material">
        <color rgba="0.9 0.9 0.9 1.0"/>
      </material>
    </visual>
  </link>
  <joint name="root_link_joint" type="fixed">
    <origin xyz="0.0 0.0 0.635" rpy="0.0 0.0 0.0"/>
    <parent link="base_footprint"/>
    <child link="root_link"/>
  </joint>
  <link name="root_link">
    <inertial>
      <origin xyz="0.003550600027665496 -0.00014959200052544475 0.024519000202417374" rpy="-0.12168199568986893 -1.5099328756332397 0.12848980724811554"/>
      <mass value="2.5750999450683594"/>
      <inertia ixx="0.0025303466245532036" ixy="0.0" ixz="0.0" iyy="0.004051563795655966" iyz="0.0" izz="0.004473471082746983"/>
    </inertial>
    <visual name="SM_root_link_visual_0">
      <origin xyz="0.0 0.0 0.3138580024242401" rpy="0.0 0.0 -1.5707963705062866"/>
      <geometry>
        <mesh filename="file://iCub/meshes/stl/sim_icub3_root_link_prt.stl" scale="0.0010000000474974513 0.0010000000474974513 0.0010000000474974513"/>
      </geometry>
      <material name="SM_root_link_visual_0_material">
        <color rgba="0.9 0.9 0.9 1.0"/>
      </material>
    </visual>
  </link>
  <joint name="r_hip_pitch" type="revolute">
    <origin xyz="0.02160000056028366 -0.040550000965595245 0.0" rpy="0.0 0.0 0.0"/>
    <axis xyz="0.0 -1.0 0.0"/>
    <parent link="root_link"/>
    <child link="r_hip_1"/>
    <limit effort="50000.0" lower="-0.7853981852531433" upper="2.0071287155151367" velocity="120.0"/>
  </joint>
  <link name="r_hip_1">
    <inertial>
      <origin xyz="-0.004106500186026096 -0.028109800070524216 -0.0008360000210814178" rpy="-1.5974873304367065 0.08284170180559158 0.1301988810300827"/>
      <mass value="2.1623001098632812"/>
      <inertia ixx="0.0021892774384468794" ixy="0.0" ixz="0.0" iyy="0.002367624081671238" iyz="0.0" izz="0.002684722887352109"/>
    </inertial>
    <visual name="SM_r_hip_1_visual_0">
      <origin xyz="-0.02160000056028366 0.040550000965595245 0.3138580024242401" rpy="0.0 0.0 -1.5707963705062866"/>
      <geometry>
        <mesh filename="file://iCub/meshes/stl/sim_icub3_r_hip_1_prt.stl" scale="0.0010000000474974513 0.0010000000474974513 0.0010000000474974513"/>
      </geometry>
      <material name="SM_r_hip_1_visual_0_material">
        <color rgba="0.9 0.9 0.9 1.0"/>
      </material>
    </visual>
  </link>
  <joint name="r_hip_roll" type="revolute">
    <origin xyz="-0.04729999974370003 -0.03310000151395798 -0.008999999612569809" rpy="0.0 0.0 0.0"/>
    <axis xyz="-1.0 0.0 0.0"/>
    <parent link="r_hip_1"/>
    <child link="r_hip_2"/>
    <limit effort="50000.0" lower="-0.1745329201221466" upper="1.9547687768936157" velocity="120.0"/>
  </joint>
  <link name="r_hip_2">
    <inertial>
      <origin xyz="-0.003963499795645475 -7.01000026310794e-05 -0.03753500059247017" rpy="1.5696773529052734 -0.7041304707527161 0.002412564819678664"/>
      <mass value="1.7731000185012817"/>
      <inertia ixx="0.002161795273423195" ixy="0.0" ixz="0.0" iyy="0.004080543760210276" iyz="0.0" izz="0.005229215137660503"/>
    </inertial>
    <visual name="SM_r_hip_2_visual_0">
      <origin xyz="0.025699999183416367 0.07365000247955322 0.3228580057621002" rpy="0.0 0.0 -1.5707963705062866"/>
      <geometry>
        <mesh filename="file://iCub/meshes/stl/sim_icub3_r_hip_2_prt.stl" scale="0.0010000000474974513 0.0010000000474974513 0.0010000000474974513"/>
      </geometry>
      <material name="SM_r_hip_2_visual_0_material">
        <color rgba="0.9 0.9 0.9 1.0"/>
      </material>
    </visual>
  </link>
  <joint name="r_hip_3_joint" type="fixed">
    <origin xyz="0.036699999999999997 0.0 -0.08969999999999995" rpy="0.0 0.0 0.0"/>
    <parent link="r_hip_2"/>
    <child link="r_hip_3"/>
  </joint>
  <link name="r_hip_3">
    <inertial>
      <origin xyz="0.0024329000152647495 0.012333700433373451 -0.038242001086473465" rpy="-0.3074113130569458 -1.1807552576065063 -1.2334580421447754"/>
      <mass value="2.1635000705718994"/>
      <inertia ixx="0.0036479178816080093" ixy="0.0" ixz="0.0" iyy="0.003731799777597189" iyz="0.0" izz="0.0040275114588439465"/>
    </inertial>
    <visual name="SM_r_hip_3_visual_0">
      <origin xyz="-0.010999999940395355 0.07365000247955322 0.412557989358902" rpy="0.0 0.0 -1.5707963705062866"/>
      <geometry>
        <mesh filename="file://iCub/meshes/stl/sim_icub3_r_hip_3_prt.stl" scale="0.0010000000474974513 0.0010000000474974513 0.0010000000474974513"/>
      </geometry>
      <material name="SM_r_hip_3_visual_0_material">
        <color rgba="0.3 0.3 0.3 1.0"/>
      </material>
    </visual>
  </link>
  <joint name="r_hip_yaw" type="revolute">
    <origin xyz="0.0 0.014999999664723873 -0.07090000063180923" rpy="0.0 0.0 0.0"/>
    <axis xyz="0.0 0.0 -1.0"/>
    <parent link="r_hip_3"/>
    <child link="r_upper_leg"/>
    <limit effort="50000.0" lower="-1.3962633609771729" upper="1.3962633609771729" velocity="120.0"/>
  </joint>
  <link name="r_upper_leg">
    <inertial>
      <origin xyz="0.005240300204604864 -0.0014998000115156174 -0.051858000457286835" rpy="0.6216620802879333 -1.3735415935516357 -0.6136392951011658"/>
      <mass value="0.9092599749565125"/>
      <inertia ixx="0.0009642461081966758" ixy="0.0" ixz="0.0" iyy="0.0018723676912486553" iyz="0.0" izz="0.0023642233572900295"/>
    </inertial>
    <visual name="SM_r_upper_leg_visual_0">
      <origin xyz="-0.010999999940395355 0.058649998158216476 0.483458012342453" rpy="0.0 0.0 -1.5707963705062866"/>
      <geometry>
        <mesh filename="file://iCub/meshes/stl/sim_icub3_r_upper_leg_prt.stl" scale="0.0010000000474974513 0.0010000000474974513 0.0010000000474974513"/>
      </geometry>
      <material name="SM_r_upper_leg_visual_0_material">
        <color rgba="0.9 0.9 0.9 1.0"/>
      </material>
    </visual>
  </link>
  <joint name="r_knee" type="revolute">
    <origin xyz="0.014999999664723873 -0.024900000542402267 -0.10620000213384628" rpy="0.0 0.0 0.0"/>
    <axis xyz="0.0 -1.0 0.0"/>
    <parent link="r_upper_leg"/>
    <child link="r_lower_leg"/>
    <limit effort="50000.0" lower="-1.2217304706573486" upper="0.0872664600610733" velocity="120.0"/>
  </joint>
  <link name="r_lower_leg">
    <inertial>
      <origin xyz="-0.013102400116622448 0.0219867005944252 -0.12726199626922607" rpy="-0.5311242341995239 -1.5650811195373535 2.0589096546173096"/>
      <mass value="5.076099872589111"/>
      <inertia ixx="0.0057839578948915005" ixy="0.0" ixz="0.0" iyy="0.05340635031461716" iyz="0.0" izz="0.05584729462862015"/>
    </inertial>
    <visual name="SM_r_lower_leg_visual_0">
      <origin xyz="-0.026000000536441803 0.08354999870061874 0.5896580219268799" rpy="0.0 0.0 -1.5707963705062866"/>
      <geometry>
        <mesh filename="file://iCub/meshes/stl/sim_icub3_r_lower_leg_prt.stl" scale="0.0010000000474974513 0.0010000000474974513 0.0010000000474974513"/>
      </geometry>
      <material name="SM_r_lower_leg_visual_0_material">
        <color rgba="0.3 0.3 0.3 1.0"/>
      </material>
    </visual>
  </link>
  <joint name="r_ankle_pitch" type="revolute">
    <origin xyz="0.0 0.0005000000237487257 -0.2559889853000641" rpy="0.0 0.0 0.0"/>
    <axis xyz="0.0 1.0 0.0"/>
    <parent link="r_lower_leg"/>
    <child link="r_ankle_1"/>
    <limit effort="50000.0" lower="-0.7853981852531433" upper="0.7853981852531433" velocity="120.0"/>
  </joint>
  <link name="r_ankle_1">
    <inertial>
      <origin xyz="-0.00566580006852746 0.0004763999895658344 -0.015185999684035778" rpy="2.5487778186798096 -0.6544567942619324 2.1996397972106934"/>
      <mass value="0.3656899929046631"/>
      <inertia ixx="0.009915976785123348" ixy="0.0" ixz="0.0" iyy="0.0100221773609519" iyz="0.0" izz="0.010061846114695072"/>
    </inertial>
    <visual name="SM_r_ankle_1_visual_0">
      <origin xyz="-0.026000000536441803 0.08304999768733978 0.8456469774246216" rpy="0.0 0.0 -1.5707963705062866"/>
      <geometry>
        <mesh filename="file://iCub/meshes/stl/sim_icub3_r_ankle_1_prt.stl" scale="0.0010000000474974513 0.0010000000474974513 0.0010000000474974513"/>
      </geometry>
      <material name="SM_r_ankle_1_visual_0_material">
        <color rgba="0.9 0.9 0.9 1.0"/>
      </material>
    </visual>
  </link>
  <joint name="r_ankle_roll" type="revolute">
    <origin xyz="-0.05274999886751175 0.018200000748038292 -0.03500000014901161" rpy="0.0 0.0 0.0"/>
    <axis xyz="-1.0 0.0 0.0"/>
    <parent link="r_ankle_1"/>
    <child link="r_ankle_2"/>
    <limit effort="50000.0" lower="-0.4363323152065277" upper="0.4363323152065277" velocity="120.0"/>
  </joint>
  <link name="r_ankle_2">
    <inertial>
      <origin xyz="0.04173709824681282 5.619999865302816e-05 -0.025592999532818794" rpy="3.1340088844299316 0.7853803038597107 3.134922742843628"/>
      <mass value="1.3770999908447266"/>
      <inertia ixx="0.008885795250535011" ixy="0.0" ixz="0.0" iyy="0.01000001560896635" iyz="0.0" izz="0.011114188469946384"/>
    </inertial>
    <visual name="SM_r_ankle_2_visual_0">
      <origin xyz="0.026750000193715096 0.06485000252723694 0.8806470036506653" rpy="0.0 0.0 -1.5707963705062866"/>
      <geometry>
        <mesh filename="file://iCub/meshes/stl/sim_icub3_r_ankle_2_prt.stl" scale="0.0010000000474974513 0.0010000000474974513 0.0010000000474974513"/>
      </geometry>
      <material name="SM_r_ankle_2_visual_0_material">
        <color rgba="0.3 0.3 0.3 1.0"/>
      </material>
    </visual>
  </link>
  <joint name="r_foot_rear_joint" type="fixed">
    <origin xyz="0.016 0.0 -0.06579999999999997" rpy="0.0 0.0 0.0"/>
    <parent link="r_ankle_2"/>
    <child link="r_foot_rear"/>
  </joint>
  <link name="r_foot_rear">
    <inertial>
      <origin xyz="0.000618099991697818 7.080000068526715e-05 0.003513999981805682" rpy="3.09427809715271 0.7752974629402161 1.1142250299453735"/>
      <mass value="0.17481780052185059"/>
      <inertia ixx="0.009996877983212471" ixy="0.0" ixz="0.0" iyy="0.010000117123126984" iyz="0.0" izz="0.010003005154430866"/>
    </inertial>
    <visual name="SM_r_foot_rear_visual_0">
      <origin xyz="0.01075000036507845 0.06485000252723694 0.9464470148086548" rpy="0.0 0.0 -1.5707963705062866"/>
      <geometry>
        <mesh filename="file://iCub/meshes/stl/sim_icub3_r_foot_rear_prt.stl" scale="0.0010000000474974513 0.0010000000474974513 0.0010000000474974513"/>
      </geometry>
      <material name="SM_r_foot_rear_visual_0_material">
        <color rgba="1.0 0.51 0.0 1.0"/>
      </material>
    </visual>
  </link>
  <joint name="r_sole_joint" type="fixed">
    <origin xyz="0.05963000000000001 0.0 0.0" rpy="0.0 0.0 0.0"/>
    <parent link="r_foot_rear"/>
    <child link="r_sole"/>
  </joint>
  <link name="r_sole">
    <inertial>
      <origin xyz="0.0 0.0 0.0" rpy="0.0 0.0 0.0"/>
      <mass value="0.0"/>
      <inertia ixx="0.0" ixy="0.0" ixz="0.0" iyy="0.0" iyz="0.0" izz="0.0"/>
    </inertial>
  </link>
  <joint name="r_foot_front_joint" type="fixed">
    <origin xyz="0.13525 0.0 -0.06579999999999997" rpy="0.0 0.0 0.0"/>
    <parent link="r_ankle_2"/>
    <child link="r_foot_front"/>
  </joint>
  <link name="r_foot_front">
    <inertial>
      <origin xyz="-0.0004180000105407089 0.00048499999684281647 0.00558099988847971" rpy="-2.9928698539733887 -0.753842830657959 -0.4887596070766449"/>
      <mass value="0.179639995098114"/>
      <inertia ixx="0.009918789379298687" ixy="0.0" ixz="0.0" iyy="0.01000821404159069" iyz="0.0" izz="0.010072996839880943"/>
    </inertial>
    <visual name="SM_r_foot_front_visual_0">
      <origin xyz="-0.10849999636411667 0.06485000252723694 0.9464470148086548" rpy="0.0 0.0 -1.5707963705062866"/>
      <geometry>
        <mesh filename="file://iCub/meshes/stl/sim_icub3_r_foot_front_prt.stl" scale="0.0010000000474974513 0.0010000000474974513 0.0010000000474974513"/>
      </geometry>
      <material name="SM_r_foot_front_visual_0_material">
        <color rgba="1.0 0.51 0.0 1.0"/>
      </material>
    </visual>
  </link>
  <joint name="l_hip_pitch" type="revolute">
    <origin xyz="0.02160000056028366 0.040449999272823334 0.0" rpy="0.0 0.0 0.0"/>
    <axis xyz="0.0 -1.0 0.0"/>
    <parent link="root_link"/>
    <child link="l_hip_1"/>
    <limit effort="50000.0" lower="-0.7853981852531433" upper="2.0071287155151367" velocity="120.0"/>
  </joint>
  <link name="l_hip_1">
    <inertial>
      <origin xyz="-0.002203499898314476 0.028797699138522148 -0.000493000028654933" rpy="-1.573423147201538 -0.10755742341279984 -0.05728795379400253"/>
      <mass value="2.1084611415863037"/>
      <inertia ixx="0.0019451569532975554" ixy="0.0" ixz="0.0" iyy="0.0021027938928455114" iyz="0.0" izz="0.002495991298928857"/>
    </inertial>
    <visual name="SM_l_hip_1_visual_0">
      <origin xyz="-0.02160000056028366 -0.040449999272823334 0.3138580024242401" rpy="0.0 0.0 -1.5707963705062866"/>
      <geometry>
        <mesh filename="file://iCub/meshes/stl/sim_icub3_l_hip_1_prt.stl" scale="0.0010000000474974513 0.0010000000474974513 0.0010000000474974513"/>
      </geometry>
      <material name="SM_l_hip_1_visual_0_material">
        <color rgba="0.9 0.9 0.9 1.0"/>
      </material>
    </visual>
  </link>
  <joint name="l_hip_roll" type="revolute">
    <origin xyz="-0.04724999889731407 0.03310000151395798 -0.008999999612569809" rpy="0.0 0.0 0.0"/>
    <axis xyz="1.0 0.0 0.0"/>
    <parent link="l_hip_1"/>
    <child link="l_hip_2"/>
    <limit effort="50000.0" lower="-0.1745329201221466" upper="2.0071287155151367" velocity="120.0"/>
  </joint>
  <link name="l_hip_2">
    <inertial>
      <origin xyz="-0.005948599893599749 8.05000017862767e-05 -0.036653000861406326" rpy="-1.569917917251587 -0.7718997597694397 -0.0020651626400649548"/>
      <mass value="1.7812706232070923"/>
      <inertia ixx="0.0019694678485393524" ixy="0.0" ixz="0.0" iyy="0.0040740203112363815" iyz="0.0" izz="0.005016930866986513"/>
    </inertial>
    <visual name="SM_l_hip_2_visual_0">
      <origin xyz="0.02565000019967556 -0.07355000078678131 0.3228580057621002" rpy="0.0 0.0 -1.5707963705062866"/>
      <geometry>
        <mesh filename="file://iCub/meshes/stl/sim_icub3_l_hip_2_prt.stl" scale="0.0010000000474974513 0.0010000000474974513 0.0010000000474974513"/>
      </geometry>
      <material name="SM_l_hip_2_visual_0_material">
        <color rgba="0.9 0.9 0.9 1.0"/>
      </material>
    </visual>
  </link>
  <joint name="l_hip_3_joint" type="fixed">
    <origin xyz="0.036699999999999997 0.0 -0.08969999999999995" rpy="0.0 0.0 0.0"/>
    <parent link="l_hip_2"/>
    <child link="l_hip_3"/>
  </joint>
  <link name="l_hip_3">
    <inertial>
      <origin xyz="0.002293400000780821 -0.012390400283038616 -0.03849299997091293" rpy="-0.31047409772872925 1.1346639394760132 -1.9040493965148926"/>
      <mass value="2.169151544570923"/>
      <inertia ixx="0.003588105086237192" ixy="0.0" ixz="0.0" iyy="0.0036453946959227324" iyz="0.0" izz="0.003943108022212982"/>
    </inertial>
    <visual name="SM_l_hip_3_visual_0">
      <origin xyz="-0.011049999855458736 -0.07355000078678131 0.412557989358902" rpy="0.0 0.0 -1.5707963705062866"/>
      <geometry>
        <mesh filename="file://iCub/meshes/stl/sim_icub3_l_hip_3_prt.stl" scale="0.0010000000474974513 0.0010000000474974513 0.0010000000474974513"/>
      </geometry>
      <material name="SM_l_hip_3_visual_0_material">
        <color rgba="0.3 0.3 0.3 1.0"/>
      </material>
    </visual>
  </link>
  <joint name="l_hip_yaw" type="revolute">
    <origin xyz="0.0 -0.014999999664723873 -0.07090000063180923" rpy="0.0 0.0 0.0"/>
    <axis xyz="0.0 0.0 1.0"/>
    <parent link="l_hip_3"/>
    <child link="l_upper_leg"/>
    <limit effort="50000.0" lower="-1.3962633609771729" upper="1.3962633609771729" velocity="120.0"/>
  </joint>
  <link name="l_upper_leg">
    <inertial>
      <origin xyz="0.006410100031644106 0.004499500151723623 -0.05761399865150452" rpy="0.9509592652320862 1.2985233068466187 -2.1936206817626953"/>
      <mass value="0.9682644605636597"/>
      <inertia ixx="0.001010193140245974" ixy="0.0" ixz="0.0" iyy="0.002193399937823415" iyz="0.0" izz="0.0026930803433060646"/>
    </inertial>
    <visual name="SM_l_upper_leg_visual_0">
      <origin xyz="-0.011049999855458736 -0.05855000019073486 0.483458012342453" rpy="0.0 0.0 -1.5707963705062866"/>
      <geometry>
        <mesh filename="file://iCub/meshes/stl/sim_icub3_l_upper_leg_prt.stl" scale="0.0010000000474974513 0.0010000000474974513 0.0010000000474974513"/>
      </geometry>
      <material name="SM_l_upper_leg_visual_0_material">
        <color rgba="0.9 0.9 0.9 1.0"/>
      </material>
    </visual>
  </link>
  <joint name="l_knee" type="revolute">
    <origin xyz="0.014999999664723873 0.024900000542402267 -0.10620000213384628" rpy="0.0 0.0 0.0"/>
    <axis xyz="0.0 -1.0 0.0"/>
    <parent link="l_upper_leg"/>
    <child link="l_lower_leg"/>
    <limit effort="50000.0" lower="-1.2217304706573486" upper="0.0872664600610733" velocity="120.0"/>
  </joint>
  <link name="l_lower_leg">
    <inertial>
      <origin xyz="-0.012714199721813202 -0.02260739915072918 -0.1281760036945343" rpy="-0.4007331430912018 -1.568082332611084 1.9971438646316528"/>
      <mass value="5.06304931640625"/>
      <inertia ixx="0.005671148654073477" ixy="0.0" ixz="0.0" iyy="0.05430392175912857" iyz="0.0" izz="0.056787341833114624"/>
    </inertial>
    <visual name="SM_l_lower_leg_visual_0">
      <origin xyz="-0.02604999952018261 -0.08344999700784683 0.5896580219268799" rpy="0.0 0.0 -1.5707963705062866"/>
      <geometry>
        <mesh filename="file://iCub/meshes/stl/sim_icub3_l_lower_leg_prt.stl" scale="0.0010000000474974513 0.0010000000474974513 0.0010000000474974513"/>
      </geometry>
      <material name="SM_l_lower_leg_visual_0_material">
        <color rgba="0.3 0.3 0.3 1.0"/>
      </material>
    </visual>
  </link>
  <joint name="l_ankle_pitch" type="revolute">
    <origin xyz="0.0 -0.0005000000237487257 -0.2559889853000641" rpy="0.0 0.0 0.0"/>
    <axis xyz="0.0 1.0 0.0"/>
    <parent link="l_lower_leg"/>
    <child link="l_ankle_1"/>
    <limit effort="50000.0" lower="-0.7853981852531433" upper="0.7853981852531433" velocity="120.0"/>
  </joint>
  <link name="l_ankle_1">
    <inertial>
      <origin xyz="-0.005967800039798021 -0.0010992999887093902 -0.01576099917292595" rpy="0.6064426898956299 -0.6494082808494568 -2.2141337394714355"/>
      <mass value="0.3461768925189972"/>
      <inertia ixx="0.009920657612383366" ixy="0.0" ixz="0.0" iyy="0.01002234686166048" iyz="0.0" izz="0.010056995786726475"/>
    </inertial>
    <visual name="SM_l_ankle_1_visual_0">
      <origin xyz="-0.02604999952018261 -0.08295000344514847 0.8456469774246216" rpy="0.0 0.0 -1.5707963705062866"/>
      <geometry>
        <mesh filename="file://iCub/meshes/stl/sim_icub3_l_ankle_1_prt.stl" scale="0.0010000000474974513 0.0010000000474974513 0.0010000000474974513"/>
      </geometry>
      <material name="SM_l_ankle_1_visual_0_material">
        <color rgba="0.9 0.9 0.9 1.0"/>
      </material>
    </visual>
  </link>
  <joint name="l_ankle_roll" type="revolute">
    <origin xyz="-0.05274999886751175 -0.018200000748038292 -0.03500000014901161" rpy="0.0 0.0 0.0"/>
    <axis xyz="1.0 0.0 0.0"/>
    <parent link="l_ankle_1"/>
    <child link="l_ankle_2"/>
    <limit effort="50000.0" lower="-0.4363323152065277" upper="0.4363323152065277" velocity="120.0"/>
  </joint>
  <link name="l_ankle_2">
    <inertial>
      <origin xyz="0.042978398501873016 -5.850000161444768e-05 -0.025988999754190445" rpy="3.1346206665039062 -0.7853778600692749 0.008246218785643578"/>
      <mass value="1.0115336179733276"/>
      <inertia ixx="0.009209319949150085" ixy="0.0" ixz="0.0" iyy="0.010000025853514671" iyz="0.0" izz="0.01079065352678299"/>
    </inertial>
    <visual name="SM_l_ankle_2_visual_0">
      <origin xyz="0.02669999934732914 -0.06475000083446503 0.8806470036506653" rpy="0.0 0.0 -1.5707963705062866"/>
      <geometry>
        <mesh filename="file://iCub/meshes/stl/sim_icub3_l_ankle_2_prt.stl" scale="0.0010000000474974513 0.0010000000474974513 0.0010000000474974513"/>
      </geometry>
      <material name="SM_l_ankle_2_visual_0_material">
        <color rgba="0.3 0.3 0.3 1.0"/>
      </material>
    </visual>
  </link>
  <joint name="l_foot_front_joint" type="fixed">
    <origin xyz="0.13524999999999998 0.0 -0.06579999999999997" rpy="0.0 0.0 0.0"/>
    <parent link="l_ankle_2"/>
    <child link="l_foot_front"/>
  </joint>
  <link name="l_foot_front">
    <inertial>
      <origin xyz="7.699999696342275e-05 -3.989999822806567e-05 0.0042570000514388084" rpy="0.014344442635774612 0.7853860855102539 -3.139211893081665"/>
      <mass value="0.1750381588935852"/>
      <inertia ixx="0.009965805336833" ixy="0.0" ixz="0.0" iyy="0.009999994188547134" iyz="0.0" izz="0.010034199804067612"/>
    </inertial>
    <visual name="SM_l_foot_front_visual_0">
      <origin xyz="-0.10854999721050262 -0.06475000083446503 0.9464470148086548" rpy="0.0 0.0 -1.5707963705062866"/>
      <geometry>
        <mesh filename="file://iCub/meshes/stl/sim_icub3_l_foot_front_prt.stl" scale="0.0010000000474974513 0.0010000000474974513 0.0010000000474974513"/>
      </geometry>
      <material name="SM_l_foot_front_visual_0_material">
        <color rgba="1.0 0.51 0.0 1.0"/>
      </material>
    </visual>
  </link>
  <joint name="l_foot_rear_joint" type="fixed">
    <origin xyz="0.016 0.0 -0.06579999999999997" rpy="0.0 0.0 0.0"/>
    <parent link="l_ankle_2"/>
    <child link="l_foot_rear"/>
  </joint>
  <link name="l_foot_rear">
    <inertial>
      <origin xyz="0.0005056000081822276 3.35000004270114e-05 0.0036589999217540026" rpy="-3.0986454486846924 -0.7773046493530273 -0.4224768877029419"/>
      <mass value="0.17459742724895477"/>
      <inertia ixx="0.009991241618990898" ixy="0.0" ixz="0.0" iyy="0.010000264272093773" iyz="0.0" izz="0.01000849436968565"/>
    </inertial>
    <visual name="SM_l_foot_rear_visual_0">
      <origin xyz="0.010700000450015068 -0.06475000083446503 0.9464470148086548" rpy="0.0 0.0 -1.5707963705062866"/>
      <geometry>
        <mesh filename="file://iCub/meshes/stl/sim_icub3_l_foot_rear_prt.stl" scale="0.0010000000474974513 0.0010000000474974513 0.0010000000474974513"/>
      </geometry>
      <material name="SM_l_foot_rear_visual_0_material">
        <color rgba="1.0 0.51 0.0 1.0"/>
      </material>
    </visual>
  </link>
  <joint name="l_sole_joint" type="fixed">
    <origin xyz="0.05963 0.0 0.0" rpy="0.0 0.0 0.0"/>
    <parent link="l_foot_rear"/>
    <child link="l_sole"/>
  </joint>
  <link name="l_sole">
    <inertial>
      <origin xyz="0.0 0.0 0.0" rpy="0.0 0.0 0.0"/>
      <mass value="0.0"/>
      <inertia ixx="0.0" ixy="0.0" ixz="0.0" iyy="0.0" iyz="0.0" izz="0.0"/>
    </inertial>
  </link>
  <joint name="torso_roll" type="revolute">
    <origin xyz="0.0 0.0 0.060499999672174454" rpy="0.0 0.0 0.0"/>
    <axis xyz="-1.0 0.0 0.0"/>
    <parent link="root_link"/>
    <child link="torso_1"/>
    <limit effort="50000.0" lower="-0.40142571926116943" upper="0.40142571926116943" velocity="120.0"/>
  </joint>
  <link name="torso_1">
    <inertial>
      <origin xyz="-0.007526319939643145 0.0006843130104243755 0.05308400094509125" rpy="1.5593100786209106 -1.142606258392334 -3.126340389251709"/>
      <mass value="1.7142624855041504"/>
      <inertia ixx="0.0019013717537745833" ixy="0.0" ixz="0.0" iyy="0.002717773662880063" iyz="0.0" izz="0.0033514495007693768"/>
    </inertial>
    <visual name="SM_torso_1_visual_0">
      <origin xyz="0.0 0.0 0.25335800647735596" rpy="0.0 0.0 -1.5707963705062866"/>
      <geometry>
        <mesh filename="file://iCub/meshes/stl/sim_icub3_torso_1_prt.stl" scale="0.0010000000474974513 0.0010000000474974513 0.0010000000474974513"/>
      </geometry>
      <material name="SM_torso_1_visual_0_material">
        <color rgba="0.9 0.9 0.9 1.0"/>
      </material>
    </visual>
  </link>
  <joint name="torso_pitch" type="revolute">
    <origin xyz="0.0 0.0 0.07249999791383743" rpy="0.0 0.0 0.0"/>
    <axis xyz="0.0 1.0 0.0"/>
    <parent link="torso_1"/>
    <child link="torso_2"/>
    <limit effort="50000.0" lower="-0.3141592741012573" upper="0.7853981852531433" velocity="120.0"/>
  </joint>
  <link name="torso_2">
    <inertial>
      <origin xyz="0.0006802239804528654 0.0015533999539911747 0.0511850006878376" rpy="-1.5011513233184814 -1.3896698951721191 1.5077036619186401"/>
      <mass value="1.3746730089187622"/>
      <inertia ixx="0.0015269903233274817" ixy="0.0" ixz="0.0" iyy="0.002160861389711499" iyz="0.0" izz="0.002710498170927167"/>
    </inertial>
    <visual name="SM_torso_2_visual_0">
      <origin xyz="0.0 0.0 0.18085800111293793" rpy="0.0 0.0 -1.5707963705062866"/>
      <geometry>
        <mesh filename="file://iCub/meshes/stl/sim_icub3_torso_2_prt.stl" scale="0.0010000000474974513 0.0010000000474974513 0.0010000000474974513"/>
      </geometry>
      <material name="SM_torso_2_visual_0_material">
        <color rgba="0.9 0.9 0.9 1.0"/>
      </material>
    </visual>
  </link>
  <joint name="torso_yaw" type="revolute">
    <origin xyz="0.0 0.0 0.06447000056505203" rpy="0.0 0.0 0.0"/>
    <axis xyz="0.0 0.0 -1.0"/>
    <parent link="torso_2"/>
    <child link="chest"/>
    <limit effort="50000.0" lower="-0.7504915595054626" upper="0.7504915595054626" velocity="120.0"/>
  </joint>
  <link name="chest">
    <inertial>
      <origin xyz="-0.005974330008029938 -7.260410347953439e-05 0.06416629999876022" rpy="1.6801563501358032 1.1712812185287476 0.07673794031143188"/>
      <mass value="7.523099899291992"/>
      <inertia ixx="0.028819739818572998" ixy="0.0" ixz="0.0" iyy="0.033708710223436356" iyz="0.0" izz="0.03386033698916435"/>
    </inertial>
    <visual name="SM_chest_visual_0">
      <origin xyz="0.0 0.0 0.1163880005478859" rpy="0.0 0.0 -1.5707963705062866"/>
      <geometry>
        <mesh filename="file://iCub/meshes/stl/sim_icub3_chest_prt.stl" scale="0.0010000000474974513 0.0010000000474974513 0.0010000000474974513"/>
      </geometry>
      <material name="SM_chest_visual_0_material">
        <color rgba="0.3 0.3 0.3 1.0"/>
      </material>
    </visual>
  </link>
  <joint name="chest_depth_frame_joint" type="fixed">
    <origin xyz="0.0894115 0.0175 0.09929950000000001" rpy="-1.5707963705062866 0.0 -1.5707963705062866"/>
    <parent link="chest"/>
    <child link="chest_depth_frame"/>
  </joint>
  <link name="chest_depth_frame">
    <inertial>
      <origin xyz="0.0 0.0 0.0" rpy="0.0 0.0 0.0"/>
      <mass value="0.0"/>
      <inertia ixx="0.0" ixy="0.0" ixz="0.0" iyy="0.0" iyz="0.0" izz="0.0"/>
    </inertial>
  </link>
  <joint name="chest_rgb_frame_joint" type="fixed">
    <origin xyz="0.0894115 -0.0115 0.09929950000000001" rpy="-1.5707963705062866 0.0 -1.5707963705062866"/>
    <parent link="chest"/>
    <child link="chest_rgb_frame"/>
  </joint>
  <link name="chest_rgb_frame">
    <inertial>
      <origin xyz="0.0 0.0 0.0" rpy="0.0 0.0 0.0"/>
      <mass value="0.0"/>
      <inertia ixx="0.0" ixy="0.0" ixz="0.0" iyy="0.0" iyz="0.0" izz="0.0"/>
    </inertial>
  </link>
  <joint name="neck_1_joint" type="fixed">
    <origin xyz="-0.00378849 0.0 0.1652995" rpy="0.0 0.0 0.0"/>
    <parent link="chest"/>
    <child link="neck_1"/>
  </joint>
  <link name="neck_1">
    <inertial>
      <origin xyz="-0.002125930041074753 0.0003375349915586412 0.031454700976610184" rpy="-2.8885064125061035 -1.410693645477295 -2.1561267375946045"/>
      <mass value="0.3680399954319"/>
      <inertia ixx="0.00017691109678708017" ixy="0.0" ixz="0.0" iyy="0.00026594477822072804" iyz="0.0" izz="0.00028811165248043835"/>
    </inertial>
    <visual name="SM_neck_1_visual_0">
      <origin xyz="0.00865000020712614 0.0 0.04899999871850014" rpy="-1.5707963705062866 0.0 -1.5707963705062866"/>
      <geometry>
        <mesh filename="file://iCub/meshes/stl/sim_head_neck_1_prt.stl" scale="0.0010000000474974513 0.0010000000474974513 0.0010000000474974513"/>
      </geometry>
      <material name="SM_neck_1_visual_0_material">
        <color rgba="0.9 0.9 0.9 1.0"/>
      </material>
    </visual>
  </link>
  <joint name="neck_pitch" type="revolute">
    <origin xyz="0.00865000020712614 0.0 0.04899999871850014" rpy="0.0 0.0 0.0"/>
    <axis xyz="0.0 -1.0 0.0"/>
    <parent link="neck_1"/>
    <child link="neck_2"/>
    <limit effort="50000.0" lower="-0.5235987901687622" upper="0.3839724361896515" velocity="120.0"/>
  </joint>
  <link name="neck_2">
    <inertial>
      <origin xyz="-0.00637560011819005 3.630929859355092e-05 0.006597499828785658" rpy="-1.574895977973938 -0.01310536079108715 0.5673624873161316"/>
      <mass value="0.12139999866485596"/>
      <inertia ixx="3.1596322514815256e-05" ixy="0.0" ixz="0.0" iyy="3.9229133108165115e-05" iyz="0.0" izz="5.163906462257728e-05"/>
    </inertial>
    <visual name="SM_neck_2_visual_0">
      <origin xyz="0.0 0.0 0.0" rpy="-1.5707963705062866 0.0 -1.5707963705062866"/>
      <geometry>
        <mesh filename="file://iCub/meshes/stl/sim_head_neck_2_prt.stl" scale="0.0010000000474974513 0.0010000000474974513 0.0010000000474974513"/>
      </geometry>
      <material name="SM_neck_2_visual_0_material">
        <color rgba="0.9 0.9 0.9 1.0"/>
      </material>
    </visual>
  </link>
  <joint name="neck_roll" type="revolute">
    <origin xyz="0.0 0.0 0.009500499814748764" rpy="0.0 0.0 0.0"/>
    <axis xyz="1.0 0.0 0.0"/>
    <parent link="neck_2"/>
    <child link="neck_3"/>
    <limit effort="50000.0" lower="-0.3490658402442932" upper="0.3490658402442932" velocity="120.0"/>
  </joint>
  <link name="neck_3">
    <inertial>
      <origin xyz="0.0012653999729081988 -8.218819857575e-05 0.03610900044441223" rpy="-0.025076502934098244 0.007022223435342312 0.14447177946567535"/>
      <mass value="0.18386000394821167"/>
      <inertia ixx="3.8463680539280176e-05" ixy="0.0" ixz="0.0" iyy="0.00010849461978068575" iyz="0.0" izz="0.00011969851038884372"/>
    </inertial>
    <visual name="SM_neck_3_visual_0">
      <origin xyz="0.0 0.0 -0.009500499814748764" rpy="-1.5707963705062866 0.0 -1.5707963705062866"/>
      <geometry>
        <mesh filename="file://iCub/meshes/stl/sim_head_neck_3_prt.stl" scale="0.0010000000474974513 0.0010000000474974513 0.0010000000474974513"/>
      </geometry>
      <material name="SM_neck_3_visual_0_material">
        <color rgba="0.9 0.9 0.9 1.0"/>
      </material>
    </visual>
  </link>
  <joint name="neck_yaw" type="revolute">
    <origin xyz="0.0 0.0 0.06915000081062317" rpy="0.0 0.0 0.0"/>
    <axis xyz="0.0 0.0 1.0"/>
    <parent link="neck_3"/>
    <child link="head"/>
    <limit effort="50000.0" lower="-0.7853981852531433" upper="0.7853981852531433" velocity="120.0"/>
  </joint>
  <link name="head">
    <inertial>
      <origin xyz="-0.02065170928835869 0.0005260310135781765 0.027897000312805176" rpy="2.9523932933807373 -0.02615549974143505 1.4650012254714966"/>
      <mass value="1.8727999925613403"/>
      <inertia ixx="0.005572326947003603" ixy="0.0" ixz="0.0" iyy="0.00741670373827219" iyz="0.0" izz="0.0076524014584720135"/>
    </inertial>
    <visual name="SM_head_visual_0">
      <origin xyz="0.0 0.0 -0.07865049690008163" rpy="-1.5707963705062866 0.0 -1.5707963705062866"/>
      <geometry>
        <mesh filename="file://iCub/meshes/stl/sim_head_head_prt.stl" scale="0.0010000000474974513 0.0010000000474974513 0.0010000000474974513"/>
      </geometry>
      <material name="SM_head_visual_0_material">
        <color rgba="0.9 0.9 0.9 1.0"/>
      </material>
    </visual>
  </link>
  <joint name="imu_frame_joint" type="fixed">
    <origin xyz="0.0035000000000000005 0.0055 0.10133400000000001" rpy="3.1415927410125732 0.0 -1.5707963705062866"/>
    <parent link="head"/>
    <child link="imu_frame"/>
  </joint>
  <link name="imu_frame">
    <inertial>
      <origin xyz="0.0 0.0 0.0" rpy="0.0 0.0 0.0"/>
      <mass value="0.0"/>
      <inertia ixx="0.0" ixy="0.0" ixz="0.0" iyy="0.0" iyz="0.0" izz="0.0"/>
    </inertial>
  </link>
  <joint name="eyes_tilt" type="revolute">
    <origin xyz="0.05000000074505806 0.0 0.014999999664723873" rpy="1.5700000524520874 0.0 3.140000104904175"/>
    <axis xyz="0.0 0.0 1.0"/>
    <parent link="head"/>
    <child link="eyes_tilt_frame"/>
    <limit effort="50000.0" lower="-0.5235987901687622" upper="0.5235987901687622" velocity="50000.0"/>
  </joint>
  <link name="eyes_tilt_frame">
    <inertial>
      <origin xyz="0.0 0.0 0.0" rpy="0.0 0.0 0.0"/>
      <mass value="0.0010000000474974513"/>
      <inertia ixx="0.0010000000474974513" ixy="0.0" ixz="0.0" iyy="0.0010000000474974513" iyz="0.0" izz="0.0010000000474974513"/>
    </inertial>
  </link>
  <joint name="l_eye_pan_joint" type="revolute">
    <origin xyz="0.0 0.0 0.03400000184774399" rpy="0.0 -1.5700000524520874 0.0"/>
    <axis xyz="0.0 -1.0 0.0"/>
    <parent link="eyes_tilt_frame"/>
    <child link="l_eye"/>
    <limit effort="50000.0" lower="-0.5235987901687622" upper="0.9599310755729675" velocity="50000.0"/>
  </joint>
  <link name="l_eye">
    <inertial>
      <origin xyz="0.0 0.0 0.0" rpy="0.0 0.0 0.0"/>
      <mass value="0.009999999776482582"/>
      <inertia ixx="0.0010000000474974513" ixy="0.0" ixz="0.0" iyy="0.0010000000474974513" iyz="0.0" izz="0.0010000000474974513"/>
    </inertial>
    <visual name="SM_l_eye_visual_0">
      <origin xyz="0.0 0.0 0.009999999776482582" rpy="0.0 0.0 0.0"/>
      <geometry>
        <sphere radius="0.019999999552965164"/>
      </geometry>
      <material name="SM_l_eye_visual_0_material">
        <color rgba="1.0 1.0 1.0 1.0"/>
      </material>
    </visual>
    <visual name="SM_l_eye_visual_1">
      <origin xyz="0.0 0.0 0.029999999329447746" rpy="0.0 0.0 0.0"/>
      <geometry>
        <cylinder radius="0.004999999888241291" length="0.0010000000474974513"/>
      </geometry>
      <material name="SM_l_eye_visual_1_material">
        <color rgba="0.1 0.1 0.1 1.0"/>
      </material>
    </visual>
  </link>
  <joint name="r_eye_pan_joint" type="revolute">
    <origin xyz="0.0 0.0 -0.03400000184774399" rpy="0.0 -1.5700000524520874 0.0"/>
    <axis xyz="0.0 -1.0 0.0"/>
    <parent link="eyes_tilt_frame"/>
    <child link="r_eye"/>
    <limit effort="50000.0" lower="-0.9599310755729675" upper="0.5235987901687622" velocity="50000.0"/>
  </joint>
  <link name="r_eye">
    <inertial>
      <origin xyz="0.0 0.0 0.0" rpy="0.0 0.0 0.0"/>
      <mass value="0.009999999776482582"/>
      <inertia ixx="0.0010000000474974513" ixy="0.0" ixz="0.0" iyy="0.0010000000474974513" iyz="0.0" izz="0.0010000000474974513"/>
    </inertial>
    <visual name="SM_r_eye_visual_0">
      <origin xyz="0.0 0.0 0.009999999776482582" rpy="0.0 0.0 0.0"/>
      <geometry>
        <sphere radius="0.019999999552965164"/>
      </geometry>
      <material name="SM_r_eye_visual_0_material">
        <color rgba="1.0 1.0 1.0 1.0"/>
      </material>
    </visual>
    <visual name="SM_r_eye_visual_1">
      <origin xyz="0.0 0.0 0.029999999329447746" rpy="0.0 0.0 0.0"/>
      <geometry>
        <cylinder radius="0.004999999888241291" length="0.0010000000474974513"/>
      </geometry>
      <material name="SM_r_eye_visual_1_material">
        <color rgba="0.1 0.1 0.1 1.0"/>
      </material>
    </visual>
  </link>
  <joint name="r_shoulder_pitch" type="revolute">
    <origin xyz="-0.02083509974181652 -0.03974229842424393 0.10520289838314056" rpy="-0.25326165556907654 2.301477479704772e-07 0.26179972290992737"/>
    <axis xyz="1.4990443730766856e-07 -1.0 -1.2401537219375314e-07"/>
    <parent link="chest"/>
    <child link="r_shoulder_1"/>
    <limit effort="50000.0" lower="-0.3490658402442932" upper="3.054326295852661" velocity="120.0"/>
  </joint>
  <link name="r_shoulder_1">
    <inertial>
      <origin xyz="0.00016744811728131026 -0.08721740543842316 0.0004507343110162765" rpy="1.2255864143371582 0.3671862781047821 -0.5486136674880981"/>
      <mass value="0.7869700193405151"/>
      <inertia ixx="0.009740661829710007" ixy="0.0" ixz="0.0" iyy="0.010040726512670517" iyz="0.0" izz="0.010218611918389797"/>
    </inertial>
    <visual name="SM_r_shoulder_1_visual_0">
      <origin xyz="0.030411234125494957 0.02914046309888363 0.019095774739980698" rpy="-0.0668872520327568 0.244452565908432 -1.8408154249191284"/>
      <geometry>
        <mesh filename="file://iCub/meshes/stl/sim_icub3_r_shoulder_1_prt.stl" scale="0.0010000000474974513 0.0010000000474974513 0.0010000000474974513"/>
      </geometry>
      <material name="SM_r_shoulder_1_visual_0_material">
        <color rgba="0.9 0.9 0.9 1.0"/>
      </material>
    </visual>
  </link>
  <joint name="r_shoulder_roll" type="revolute">
    <origin xyz="0.007489008363336325 -0.11150041222572327 0.00040278589585796" rpy="0.17453306913375854 -0.053747791796922684 -6.13233282820147e-07"/>
    <axis xyz="-0.9999998211860657 4.210501458601357e-08 2.4630480766063556e-08"/>
    <parent link="r_shoulder_1"/>
    <child link="r_shoulder_2"/>
    <limit effort="50000.0" lower="0.20943951606750488" upper="2.8448867797851562" velocity="120.0"/>
  </joint>
  <link name="r_shoulder_2">
    <inertial>
      <origin xyz="0.005108925048261881 -0.00021262472728267312 -0.020403359085321426" rpy="-0.06241356208920479 -0.43705710768699646 -2.2043561935424805"/>
      <mass value="0.424919992685318"/>
      <inertia ixx="0.009874754585325718" ixy="0.0" ixz="0.0" iyy="0.010047122836112976" iyz="0.0" izz="0.010078122839331627"/>
    </inertial>
    <visual name="SM_r_shoulder_2_visual_0">
      <origin xyz="0.023893259465694427 0.14064089953899384 0.017434528097510338" rpy="-0.12008540332317352 0.2297886610031128 -1.8533143997192383"/>
      <geometry>
        <mesh filename="file://iCub/meshes/stl/sim_icub3_r_shoulder_2_prt.stl" scale="0.0010000000474974513 0.0010000000474974513 0.0010000000474974513"/>
      </geometry>
      <material name="SM_r_shoulder_2_visual_0_material">
        <color rgba="0.9 0.9 0.9 1.0"/>
      </material>
    </visual>
  </link>
  <joint name="r_shoulder_3_joint" type="fixed">
    <origin xyz="-0.006849946385389872 2.1904996058697002e-07 -0.05429998157789099" rpy="0.0 0.0 0.0"/>
    <parent link="r_shoulder_2"/>
    <child link="r_shoulder_3"/>
  </joint>
  <link name="r_shoulder_3">
    <inertial>
      <origin xyz="-8.296442683786154e-05 -3.030926745850593e-05 -0.007966520264744759" rpy="-2.915469169616699 0.7336601614952087 -0.68442302942276"/>
      <mass value="0.26249998807907104"/>
      <inertia ixx="0.009988508187234402" ixy="0.0" ixz="0.0" iyy="0.009998657740652561" iyz="0.0" izz="0.010012834332883358"/>
    </inertial>
    <visual name="SM_r_shoulder_3_visual_0">
      <origin xyz="0.030743205919861794 0.14064067602157593 0.07173451036214828" rpy="-0.12008540332317352 0.2297886610031128 -1.8533143997192383"/>
      <geometry>
        <mesh filename="file://iCub/meshes/stl/sim_icub3_r_shoulder_3_prt.stl" scale="0.0010000000474974513 0.0010000000474974513 0.0010000000474974513"/>
      </geometry>
      <material name="SM_r_shoulder_3_visual_0_material">
        <color rgba="0.9 0.9 0.9 1.0"/>
      </material>
    </visual>
  </link>
  <joint name="r_shoulder_yaw" type="revolute">
    <origin xyz="0.0 4.2183273762930185e-07 -0.022499941289424896" rpy="0.0 0.0 0.0"/>
    <axis xyz="-3.787621949413733e-08 2.80519767414944e-08 1.000000238418579"/>
    <parent link="r_shoulder_3"/>
    <child link="r_upper_arm"/>
    <limit effort="50000.0" lower="-0.8726646304130554" upper="1.3962633609771729" velocity="120.0"/>
  </joint>
  <link name="r_upper_arm">
    <inertial>
      <origin xyz="0.0010476388270035386 -0.0025596260093152523 -0.05065314844250679" rpy="-2.762407064437866 -1.2331589460372925 -1.5014433860778809"/>
      <mass value="1.621899962425232"/>
      <inertia ixx="0.0012327951844781637" ixy="0.0" ixz="0.0" iyy="0.002889610594138503" iyz="0.0" izz="0.0029981478583067656"/>
    </inertial>
    <visual name="SM_r_upper_arm_visual_0">
      <origin xyz="0.030743123963475227 0.1406402587890625 0.09423445165157318" rpy="-0.12008540332317352 0.2297886610031128 -1.8533143997192383"/>
      <geometry>
        <mesh filename="file://iCub/meshes/stl/sim_icub3_r_upperarm_prt.stl" scale="0.0010000000474974513 0.0010000000474974513 0.0010000000474974513"/>
      </geometry>
      <material name="SM_r_upper_arm_visual_0_material">
        <color rgba="0.3 0.3 0.3 1.0"/>
      </material>
    </visual>
  </link>
  <joint name="r_elbow" type="revolute">
    <origin xyz="0.009999931789934635 0.001499640173278749 -0.1237003356218338" rpy="0.0 0.0 0.0"/>
    <axis xyz="2.4949582666522474e-07 -1.000000238418579 2.7942487434984287e-08"/>
    <parent link="r_upper_arm"/>
    <child link="r_elbow_1"/>
    <limit effort="50000.0" lower="-0.05235987901687622" upper="1.3089969158172607" velocity="120.0"/>
  </joint>
  <link name="r_elbow_1">
    <inertial>
      <origin xyz="-0.009961389005184174 -0.0004824674397241324 -0.014881572686135769" rpy="0.3625149130821228 -0.6373156905174255 -1.7598190307617188"/>
      <mass value="0.2215700000524521"/>
      <inertia ixx="0.009975533001124859" ixy="0.0" ixz="0.0" iyy="0.010000602342188358" iyz="0.0" izz="0.010023864917457104"/>
    </inertial>
    <visual name="SM_r_elbow_1_visual_0">
      <origin xyz="0.020743191242218018 0.13914062082767487 0.21793478727340698" rpy="-0.12008540332317352 0.2297886610031128 -1.8533143997192383"/>
      <geometry>
        <mesh filename="file://iCub/meshes/stl/sim_icub3_r_elbow_1_prt.stl" scale="0.0010000000474974513 0.0010000000474974513 0.0010000000474974513"/>
      </geometry>
      <material name="SM_r_elbow_1_visual_0_material">
        <color rgba="0.3 0.3 0.3 1.0"/>
      </material>
    </visual>
  </link>
  <joint name="r_wrist_prosup" type="revolute">
    <origin xyz="-0.014999869279563427 -0.001999649917706847 -0.055300064384937286" rpy="0.0 0.0 0.0"/>
    <axis xyz="-3.787621949413733e-08 2.80519767414944e-08 1.000000238418579"/>
    <parent link="r_elbow_1"/>
    <child link="r_forearm"/>
    <limit effort="50000.0" lower="-1.535889744758606" upper="1.535889744758606" velocity="120.0"/>
  </joint>
  <link name="r_forearm">
    <inertial>
      <origin xyz="-0.005904319696128368 -3.491232291708002e-06 -0.030210372060537338" rpy="2.808295249938965 1.3229855298995972 1.7654482126235962"/>
      <mass value="0.8686000108718872"/>
      <inertia ixx="0.0005981656722724438" ixy="0.0" ixz="0.0" iyy="0.0012388339964672923" iyz="0.0" izz="0.0012617256725206971"/>
    </inertial>
    <visual name="SM_r_forearm_visual_0">
      <origin xyz="0.03574306145310402 0.14114026725292206 0.27323484420776367" rpy="-0.12008540332317352 0.2297886610031128 -1.8533143997192383"/>
      <geometry>
        <mesh filename="file://iCub/meshes/stl/sim_icub3_r_forearm_prt.stl" scale="0.0010000000474974513 0.0010000000474974513 0.0010000000474974513"/>
      </geometry>
      <material name="SM_r_forearm_visual_0_material">
        <color rgba="0.3 0.3 0.3 1.0"/>
      </material>
    </visual>
  </link>
  <joint name="r_wrist_pitch" type="revolute">
    <origin xyz="0.016299953684210777 -0.002007442992180586 -0.10750007629394531" rpy="0.0 0.0 0.0"/>
    <axis xyz="0.9999998211860657 -4.210501458601357e-08 -2.4630480766063556e-08"/>
    <parent link="r_forearm"/>
    <child link="r_wrist_1"/>
    <limit effort="50000.0" lower="-1.2217304706573486" upper="0.4363323152065277" velocity="120.0"/>
  </joint>
  <link name="r_wrist_1">
    <inertial>
      <origin xyz="-0.014340376481413841 0.0005016179056838155 -0.0001151262695202604" rpy="1.8446106910705566 0.11250476539134979 -2.0941362380981445"/>
      <mass value="0.03318300098180771"/>
      <inertia ixx="0.009999112226068974" ixy="0.0" ixz="0.0" iyy="0.009999994188547134" iyz="0.0" izz="0.010000893846154213"/>
    </inertial>
    <visual name="SM_r_wrist_1_visual_0">
      <origin xyz="0.019443107768893242 0.14314770698547363 0.380734920501709" rpy="-0.12008540332317352 0.2297886610031128 -1.8533143997192383"/>
      <geometry>
        <mesh filename="file://iCub/meshes/stl/sim_icub3_r_wrist_1_prt.stl" scale="0.0010000000474974513 0.0010000000474974513 0.0010000000474974513"/>
      </geometry>
      <material name="SM_r_wrist_1_visual_0_material">
        <color rgba="0.9 0.9 0.9 1.0"/>
      </material>
    </visual>
  </link>
  <joint name="r_wrist_yaw" type="revolute">
    <origin xyz="-0.016300123184919357 0.006999390199780464 0.0" rpy="0.0 -1.5707963705062866 3.1415927410125732"/>
    <axis xyz="-2.4949582666522474e-07 -1.000000238418579 -2.7942487434984287e-08"/>
    <parent link="r_wrist_1"/>
    <child link="r_hand"/>
    <limit effort="50000.0" lower="-0.2617993950843811" upper="0.6108652353286743" velocity="120.0"/>
  </joint>
  <link name="r_hand">
    <inertial>
      <origin xyz="0.004771493375301361 0.006220157723873854 -0.06696908175945282" rpy="0.9996156096458435 -0.5033347010612488 -1.763921856880188"/>
      <mass value="0.2570500075817108"/>
      <inertia ixx="0.009942249394953251" ixy="0.0" ixz="0.0" iyy="0.009974818676710129" iyz="0.0" izz="0.010082932189106941"/>
    </inertial>
    <visual name="SM_r_hand_visual_0">
      <origin xyz="0.0027160674799233675 -0.0015567999798804522 -0.0024823539424687624" rpy="-1.5707963705062866 0.26179930567741394 2.069615773247005e-13"/>
      <geometry>
        <mesh filename="file://iCub/meshes/stl/full_RightHandPalm.stl" scale="1.0 1.0 1.0"/>
      </geometry>
      <material name="SM_r_hand_visual_0_material">
        <color rgba="0.9 0.9 0.9 1.0"/>
      </material>
    </visual>
    <visual name="SM_r_hand_visual_1">
      <origin xyz="-0.05765429884195328 -0.005556799937039614 0.013693831861019135" rpy="-1.5707963705062866 -0.26179930567741394 3.1415927410125732"/>
      <geometry>
        <mesh filename="file://iCub/meshes/stl/full_RightTopCover.stl" scale="0.0010000000474974513 0.0010000000474974513 0.0010000000474974513"/>
      </geometry>
      <material name="SM_r_hand_visual_1_material">
        <color rgba="0.9 0.9 0.9 1.0"/>
      </material>
    </visual>
  </link>
  <joint name="r_hand_thumb_0_joint" type="revolute">
    <origin xyz="-0.0318492129445076 -0.004056800156831741 0.019202696159482002" rpy="0.0880846381187439 -1.3239694833755493 2.975843906402588"/>
    <axis xyz="0.0 0.0 1.0"/>
    <parent link="r_hand"/>
    <child link="r_hand_thumb_0"/>
    <limit effort="50000.0" lower="0.0" upper="1.5707963705062866" velocity="50000.0"/>
  </joint>
  <link name="r_hand_thumb_0">
    <inertial>
      <origin xyz="0.0 0.0 0.0" rpy="0.0 0.0 0.0"/>
      <mass value="0.009999999776482582"/>
      <inertia ixx="0.0010000000474974513" ixy="0.0" ixz="0.0" iyy="0.0010000000474974513" iyz="0.0" izz="0.0010000000474974513"/>
    </inertial>
    <visual name="SM_r_hand_thumb_0_visual_0">
      <origin xyz="0.0 0.0 0.0" rpy="0.0 3.1415927410125732 1.5707963705062866"/>
      <geometry>
        <mesh filename="file://iCub/meshes/stl/full_RightThumb0.stl" scale="1.0 1.0 1.0"/>
      </geometry>
      <material name="SM_r_hand_thumb_0_visual_0_material">
        <color rgba="0.9 0.9 0.9 1.0"/>
      </material>
    </visual>
  </link>
  <joint name="r_hand_thumb_1_joint" type="revolute">
    <origin xyz="0.0210999995470047 0.004900000058114529 -3.0003846730283755e-19" rpy="-1.5707963705062866 0.0 0.0"/>
    <axis xyz="0.0 0.0 1.0"/>
    <parent link="r_hand_thumb_0"/>
    <child link="r_hand_thumb_1"/>
    <limit effort="50000.0" lower="0.0" upper="1.5707963705062866" velocity="50000.0"/>
  </joint>
  <link name="r_hand_thumb_1">
    <inertial>
      <origin xyz="0.0 0.0 0.0" rpy="0.0 0.0 0.0"/>
      <mass value="0.009999999776482582"/>
      <inertia ixx="0.0010000000474974513" ixy="0.0" ixz="0.0" iyy="0.0010000000474974513" iyz="0.0" izz="0.0010000000474974513"/>
    </inertial>
    <visual name="SM_r_hand_thumb_1_visual_0">
      <origin xyz="0.0 0.0 0.0" rpy="3.1415927410125732 0.0 0.0"/>
      <geometry>
        <mesh filename="file://iCub/meshes/stl/full_RightThumb1.stl" scale="1.0 1.0 1.0"/>
      </geometry>
      <material name="SM_r_hand_thumb_1_visual_0_material">
        <color rgba="0.9 0.9 0.9 1.0"/>
      </material>
    </visual>
  </link>
  <joint name="r_hand_thumb_2_joint" type="revolute">
    <origin xyz="0.026000000536441803 0.0 0.0" rpy="0.0 0.0 0.0"/>
    <axis xyz="0.0 0.0 1.0"/>
    <parent link="r_hand_thumb_1"/>
    <child link="r_hand_thumb_2"/>
    <limit effort="50000.0" lower="0.0" upper="1.5707963705062866" velocity="50000.0"/>
  </joint>
  <link name="r_hand_thumb_2">
    <inertial>
      <origin xyz="0.0 0.0 0.0" rpy="0.0 0.0 0.0"/>
      <mass value="0.009999999776482582"/>
      <inertia ixx="0.0010000000474974513" ixy="0.0" ixz="0.0" iyy="0.0010000000474974513" iyz="0.0" izz="0.0010000000474974513"/>
    </inertial>
    <visual name="SM_r_hand_thumb_2_visual_0">
      <origin xyz="0.0 0.0 0.0" rpy="3.1415927410125732 0.0 0.0"/>
      <geometry>
        <mesh filename="file://iCub/meshes/stl/full_RightThumb2.stl" scale="1.0 1.0 1.0"/>
      </geometry>
      <material name="SM_r_hand_thumb_2_visual_0_material">
        <color rgba="0.9 0.9 0.9 1.0"/>
      </material>
    </visual>
  </link>
  <joint name="r_hand_thumb_3_joint" type="revolute">
    <origin xyz="0.02199999988079071 0.0 0.0" rpy="0.0 0.0 0.0"/>
    <axis xyz="0.0 0.0 1.0"/>
    <parent link="r_hand_thumb_2"/>
    <child link="r_hand_thumb_3"/>
    <limit effort="50000.0" lower="0.0" upper="1.5707963705062866" velocity="50000.0"/>
  </joint>
  <link name="r_hand_thumb_3">
    <inertial>
      <origin xyz="0.0 0.0 0.0" rpy="0.0 0.0 0.0"/>
      <mass value="0.009999999776482582"/>
      <inertia ixx="0.0010000000474974513" ixy="0.0" ixz="0.0" iyy="0.0010000000474974513" iyz="0.0" izz="0.0010000000474974513"/>
    </inertial>
    <visual name="SM_r_hand_thumb_3_visual_0">
      <origin xyz="0.0 0.0 0.0" rpy="0.0 0.0 3.1415927410125732"/>
      <geometry>
        <mesh filename="file://iCub/meshes/stl/full_RightThumb3.stl" scale="1.0 1.0 1.0"/>
      </geometry>
      <material name="SM_r_hand_thumb_3_visual_0_material">
        <color rgba="0.9 0.9 0.9 1.0"/>
      </material>
    </visual>
  </link>
  <joint name="r_hand_thumb_tip_joint" type="fixed">
    <origin xyz="0.0168 0.0 0.0" rpy="-1.5707963705062866 0.0 0.0"/>
    <parent link="r_hand_thumb_3"/>
    <child link="r_hand_thumb_tip"/>
  </joint>
  <link name="r_hand_thumb_tip">
    <inertial>
      <origin xyz="0.0 0.0 0.0" rpy="0.0 0.0 0.0"/>
      <mass value="0.0"/>
      <inertia ixx="0.0" ixy="0.0" ixz="0.0" iyy="0.0" iyz="0.0" izz="0.0"/>
    </inertial>
  </link>
  <joint name="r_hand_index_0_joint" type="revolute">
    <origin xyz="-0.05255843326449394 0.005143200047314167 0.039473339915275574" rpy="1.4815961122512817 -2.8085129261016846 0.0065938569605350494"/>
    <axis xyz="0.0 0.0 1.0"/>
    <parent link="r_hand"/>
    <child link="r_hand_index_0"/>
    <limit effort="50000.0" lower="-0.3490658402442932" upper="0.0" velocity="50000.0"/>
  </joint>
  <link name="r_hand_index_0">
    <inertial>
      <origin xyz="0.0 0.0 0.0" rpy="0.0 0.0 0.0"/>
      <mass value="0.009999999776482582"/>
      <inertia ixx="0.0010000000474974513" ixy="0.0" ixz="0.0" iyy="0.0010000000474974513" iyz="0.0" izz="0.0010000000474974513"/>
    </inertial>
    <visual name="SM_r_hand_index_0_visual_0">
      <origin xyz="0.0 0.0 0.0" rpy="3.1415927410125732 0.0 3.1415927410125732"/>
      <geometry>
        <mesh filename="file://iCub/meshes/stl/full_RightIndex0.stl" scale="1.0 1.0 1.0"/>
      </geometry>
      <material name="SM_r_hand_index_0_visual_0_material">
        <color rgba="0.9 0.9 0.9 1.0"/>
      </material>
    </visual>
  </link>
  <joint name="r_hand_index_1_joint" type="revolute">
    <origin xyz="0.014800000004470348 0.0017500000540167093 -1.0715659546529912e-19" rpy="1.5707963705062866 0.0 0.0"/>
    <axis xyz="0.0 0.0 1.0"/>
    <parent link="r_hand_index_0"/>
    <child link="r_hand_index_1"/>
    <limit effort="50000.0" lower="0.0" upper="1.5707963705062866" velocity="50000.0"/>
  </joint>
  <link name="r_hand_index_1">
    <inertial>
      <origin xyz="0.0 0.0 0.0" rpy="0.0 0.0 0.0"/>
      <mass value="0.009999999776482582"/>
      <inertia ixx="0.0010000000474974513" ixy="0.0" ixz="0.0" iyy="0.0010000000474974513" iyz="0.0" izz="0.0010000000474974513"/>
    </inertial>
    <visual name="SM_r_hand_index_1_visual_0">
      <origin xyz="0.0 0.0 0.0" rpy="3.1415927410125732 0.0 0.0"/>
      <geometry>
        <mesh filename="file://iCub/meshes/stl/full_RightIndex1.stl" scale="1.0 1.0 1.0"/>
      </geometry>
      <material name="SM_r_hand_index_1_visual_0_material">
        <color rgba="0.9 0.9 0.9 1.0"/>
      </material>
    </visual>
  </link>
  <joint name="r_hand_index_2_joint" type="revolute">
    <origin xyz="0.02590000070631504 0.0 0.0" rpy="0.0 0.0 0.0"/>
    <axis xyz="0.0 0.0 1.0"/>
    <parent link="r_hand_index_1"/>
    <child link="r_hand_index_2"/>
    <limit effort="50000.0" lower="0.0" upper="1.5707963705062866" velocity="50000.0"/>
  </joint>
  <link name="r_hand_index_2">
    <inertial>
      <origin xyz="0.0 0.0 0.0" rpy="0.0 0.0 0.0"/>
      <mass value="0.009999999776482582"/>
      <inertia ixx="0.0010000000474974513" ixy="0.0" ixz="0.0" iyy="0.0010000000474974513" iyz="0.0" izz="0.0010000000474974513"/>
    </inertial>
    <visual name="SM_r_hand_index_2_visual_0">
      <origin xyz="0.0 0.0 0.0" rpy="3.1415927410125732 0.0 0.0"/>
      <geometry>
        <mesh filename="file://iCub/meshes/stl/full_RightIndex2.stl" scale="1.0 1.0 1.0"/>
      </geometry>
      <material name="SM_r_hand_index_2_visual_0_material">
        <color rgba="0.9 0.9 0.9 1.0"/>
      </material>
    </visual>
  </link>
  <joint name="r_hand_index_3_joint" type="revolute">
    <origin xyz="0.02199999988079071 0.0 0.0" rpy="0.0 0.0 0.0"/>
    <axis xyz="0.0 0.0 1.0"/>
    <parent link="r_hand_index_2"/>
    <child link="r_hand_index_3"/>
    <limit effort="50000.0" lower="0.0" upper="1.5707963705062866" velocity="50000.0"/>
  </joint>
  <link name="r_hand_index_3">
    <inertial>
      <origin xyz="0.0 0.0 0.0" rpy="0.0 0.0 0.0"/>
      <mass value="0.009999999776482582"/>
      <inertia ixx="0.0010000000474974513" ixy="0.0" ixz="0.0" iyy="0.0010000000474974513" iyz="0.0" izz="0.0010000000474974513"/>
    </inertial>
    <visual name="SM_r_hand_index_3_visual_0">
      <origin xyz="0.0 0.0 0.0" rpy="3.1415927410125732 0.0 3.1415927410125732"/>
      <geometry>
        <mesh filename="file://iCub/meshes/stl/full_RightIndex3.stl" scale="1.0 1.0 1.0"/>
      </geometry>
      <material name="SM_r_hand_index_3_visual_0_material">
        <color rgba="0.9 0.9 0.9 1.0"/>
      </material>
    </visual>
  </link>
  <joint name="r_hand_index_tip_joint" type="fixed">
    <origin xyz="0.0168 0.0 0.0" rpy="-1.5707963705062866 0.0 0.0"/>
    <parent link="r_hand_index_3"/>
    <child link="r_hand_index_tip"/>
  </joint>
  <link name="r_hand_index_tip">
    <inertial>
      <origin xyz="0.0 0.0 0.0" rpy="0.0 0.0 0.0"/>
      <mass value="0.0"/>
      <inertia ixx="0.0" ixy="0.0" ixz="0.0" iyy="0.0" iyz="0.0" izz="0.0"/>
    </inertial>
  </link>
  <joint name="r_hand_middle_0_joint" type="revolute">
    <origin xyz="-0.05754045024514198 0.0060431999154388905 0.023777974769473076" rpy="1.5707963705062866 -2.879793405532837 2.0650148258027912e-13"/>
    <axis xyz="0.0 0.0 1.0"/>
    <parent link="r_hand"/>
    <child link="r_hand_middle_0"/>
    <limit effort="50000.0" lower="0.0" upper="0.3490658503988659" velocity="50000.0"/>
  </joint>
  <link name="r_hand_middle_0">
    <inertial>
      <origin xyz="0.0 0.0 0.0" rpy="0.0 0.0 0.0"/>
      <mass value="0.009999999776482582"/>
      <inertia ixx="0.0010000000474974513" ixy="0.0" ixz="0.0" iyy="0.0010000000474974513" iyz="0.0" izz="0.0010000000474974513"/>
    </inertial>
    <visual name="SM_r_hand_middle_0_visual_0">
      <origin xyz="0.0 0.0 0.0035000001080334187" rpy="0.0 0.0 0.0"/>
      <geometry>
        <mesh filename="file://iCub/meshes/stl/full_RightMiddle0.stl" scale="1.0 1.0 1.0"/>
      </geometry>
      <material name="SM_r_hand_middle_0_visual_0_material">
        <color rgba="0.9 0.9 0.9 1.0"/>
      </material>
    </visual>
  </link>
  <joint name="r_hand_middle_1_joint" type="revolute">
    <origin xyz="0.015300000086426735 0.002199999988079071 -1.3471114489217688e-19" rpy="1.5707963705062866 0.0 0.0"/>
    <axis xyz="0.0 0.0 1.0"/>
    <parent link="r_hand_middle_0"/>
    <child link="r_hand_middle_1"/>
    <limit effort="50000.0" lower="0.0" upper="1.5707963705062866" velocity="50000.0"/>
  </joint>
  <link name="r_hand_middle_1">
    <inertial>
      <origin xyz="0.0 0.0 0.0" rpy="0.0 0.0 0.0"/>
      <mass value="0.009999999776482582"/>
      <inertia ixx="0.0010000000474974513" ixy="0.0" ixz="0.0" iyy="0.0010000000474974513" iyz="0.0" izz="0.0010000000474974513"/>
    </inertial>
    <visual name="SM_r_hand_middle_1_visual_0">
      <origin xyz="0.0 0.0 0.0" rpy="3.1415927410125732 0.0 0.0"/>
      <geometry>
        <mesh filename="file://iCub/meshes/stl/full_RightMiddle1.stl" scale="1.0 1.0 1.0"/>
      </geometry>
      <material name="SM_r_hand_middle_1_visual_0_material">
        <color rgba="0.9 0.9 0.9 1.0"/>
      </material>
    </visual>
  </link>
  <joint name="r_hand_middle_2_joint" type="revolute">
    <origin xyz="0.025800000876188278 0.0 0.0" rpy="0.0 0.0 0.0"/>
    <axis xyz="0.0 0.0 1.0"/>
    <parent link="r_hand_middle_1"/>
    <child link="r_hand_middle_2"/>
    <limit effort="50000.0" lower="0.0" upper="1.5707963705062866" velocity="50000.0"/>
  </joint>
  <link name="r_hand_middle_2">
    <inertial>
      <origin xyz="0.0 0.0 0.0" rpy="0.0 0.0 0.0"/>
      <mass value="0.009999999776482582"/>
      <inertia ixx="0.0010000000474974513" ixy="0.0" ixz="0.0" iyy="0.0010000000474974513" iyz="0.0" izz="0.0010000000474974513"/>
    </inertial>
    <visual name="SM_r_hand_middle_2_visual_0">
      <origin xyz="0.0 0.0 0.0" rpy="0.0 0.0 3.1415927410125732"/>
      <geometry>
        <mesh filename="file://iCub/meshes/stl/full_RightMiddle2.stl" scale="1.0 1.0 1.0"/>
      </geometry>
      <material name="SM_r_hand_middle_2_visual_0_material">
        <color rgba="0.9 0.9 0.9 1.0"/>
      </material>
    </visual>
  </link>
  <joint name="r_hand_middle_3_joint" type="revolute">
    <origin xyz="0.024000000208616257 0.0 0.0" rpy="0.0 0.0 0.0"/>
    <axis xyz="0.0 0.0 1.0"/>
    <parent link="r_hand_middle_2"/>
    <child link="r_hand_middle_3"/>
    <limit effort="50000.0" lower="0.0" upper="1.5707963705062866" velocity="50000.0"/>
  </joint>
  <link name="r_hand_middle_3">
    <inertial>
      <origin xyz="0.0 0.0 0.0" rpy="0.0 0.0 0.0"/>
      <mass value="0.009999999776482582"/>
      <inertia ixx="0.0010000000474974513" ixy="0.0" ixz="0.0" iyy="0.0010000000474974513" iyz="0.0" izz="0.0010000000474974513"/>
    </inertial>
    <visual name="SM_r_hand_middle_3_visual_0">
      <origin xyz="0.0 0.0 0.0" rpy="0.0 0.0 3.1415927410125732"/>
      <geometry>
        <mesh filename="file://iCub/meshes/stl/full_RightMiddle3.stl" scale="1.0 1.0 1.0"/>
      </geometry>
      <material name="SM_r_hand_middle_3_visual_0_material">
        <color rgba="0.9 0.9 0.9 1.0"/>
      </material>
    </visual>
  </link>
  <joint name="r_hand_middle_tip_joint" type="fixed">
    <origin xyz="0.0168 0.0 0.0" rpy="-1.5707963705062866 0.0 0.0"/>
    <parent link="r_hand_middle_3"/>
    <child link="r_hand_middle_tip"/>
  </joint>
  <link name="r_hand_middle_tip">
    <inertial>
      <origin xyz="0.0 0.0 0.0" rpy="0.0 0.0 0.0"/>
      <mass value="0.0"/>
      <inertia ixx="0.0" ixy="0.0" ixz="0.0" iyy="0.0" iyz="0.0" izz="0.0"/>
    </inertial>
  </link>
  <joint name="r_hand_ring_0_joint" type="revolute">
    <origin xyz="-0.06069108471274376 0.0054432000033557415 0.008658226579427719" rpy="-1.547965407371521 -0.15434306859970093 3.0537750720977783"/>
    <axis xyz="0.0 0.0 1.0"/>
    <parent link="r_hand"/>
    <child link="r_hand_ring_0"/>
    <limit effort="50000.0" lower="0.0" upper="0.3490658402442932" velocity="50000.0"/>
  </joint>
  <link name="r_hand_ring_0">
    <inertial>
      <origin xyz="0.0 0.0 0.0" rpy="0.0 0.0 0.0"/>
      <mass value="0.009999999776482582"/>
      <inertia ixx="0.0010000000474974513" ixy="0.0" ixz="0.0" iyy="0.0010000000474974513" iyz="0.0" izz="0.0010000000474974513"/>
    </inertial>
    <visual name="SM_r_hand_ring_0_visual_0">
      <origin xyz="0.0 0.0 0.0" rpy="3.1415927410125732 0.0 3.1415927410125732"/>
      <geometry>
        <mesh filename="file://iCub/meshes/stl/full_RightRing0.stl" scale="1.0 1.0 1.0"/>
      </geometry>
      <material name="SM_r_hand_ring_0_visual_0_material">
        <color rgba="0.9 0.9 0.9 1.0"/>
      </material>
    </visual>
  </link>
  <joint name="r_hand_ring_1_joint" type="revolute">
    <origin xyz="0.014800000004470348 0.0017500000540167093 -1.0715659546529912e-19" rpy="1.5707963705062866 0.0 0.0"/>
    <axis xyz="0.0 0.0 1.0"/>
    <parent link="r_hand_ring_0"/>
    <child link="r_hand_ring_1"/>
    <limit effort="50000.0" lower="0.0" upper="1.5707963705062866" velocity="50000.0"/>
  </joint>
  <link name="r_hand_ring_1">
    <inertial>
      <origin xyz="0.0 0.0 0.0" rpy="0.0 0.0 0.0"/>
      <mass value="0.009999999776482582"/>
      <inertia ixx="0.0010000000474974513" ixy="0.0" ixz="0.0" iyy="0.0010000000474974513" iyz="0.0" izz="0.0010000000474974513"/>
    </inertial>
    <visual name="SM_r_hand_ring_1_visual_0">
      <origin xyz="0.0 0.0 0.0" rpy="0.0 0.0 0.0"/>
      <geometry>
        <mesh filename="file://iCub/meshes/stl/full_RightRing1.stl" scale="1.0 1.0 1.0"/>
      </geometry>
      <material name="SM_r_hand_ring_1_visual_0_material">
        <color rgba="0.9 0.9 0.9 1.0"/>
      </material>
    </visual>
  </link>
  <joint name="r_hand_ring_2_joint" type="revolute">
    <origin xyz="0.02590000070631504 0.0 0.0" rpy="0.0 0.0 0.0"/>
    <axis xyz="0.0 0.0 1.0"/>
    <parent link="r_hand_ring_1"/>
    <child link="r_hand_ring_2"/>
    <limit effort="50000.0" lower="0.0" upper="1.5707963705062866" velocity="50000.0"/>
  </joint>
  <link name="r_hand_ring_2">
    <inertial>
      <origin xyz="0.0 0.0 0.0" rpy="0.0 0.0 0.0"/>
      <mass value="0.009999999776482582"/>
      <inertia ixx="0.0010000000474974513" ixy="0.0" ixz="0.0" iyy="0.0010000000474974513" iyz="0.0" izz="0.0010000000474974513"/>
    </inertial>
    <visual name="SM_r_hand_ring_2_visual_0">
      <origin xyz="0.0 0.0 0.0" rpy="3.1415927410125732 0.0 0.0"/>
      <geometry>
        <mesh filename="file://iCub/meshes/stl/full_RightRing2.stl" scale="1.0 1.0 1.0"/>
      </geometry>
      <material name="SM_r_hand_ring_2_visual_0_material">
        <color rgba="0.9 0.9 0.9 1.0"/>
      </material>
    </visual>
  </link>
  <joint name="r_hand_ring_3_joint" type="revolute">
    <origin xyz="0.02199999988079071 0.0 0.0" rpy="0.0 0.0 0.0"/>
    <axis xyz="0.0 0.0 1.0"/>
    <parent link="r_hand_ring_2"/>
    <child link="r_hand_ring_3"/>
    <limit effort="50000.0" lower="0.0" upper="1.5707963705062866" velocity="50000.0"/>
  </joint>
  <link name="r_hand_ring_3">
    <inertial>
      <origin xyz="0.0 0.0 0.0" rpy="0.0 0.0 0.0"/>
      <mass value="0.009999999776482582"/>
      <inertia ixx="0.0010000000474974513" ixy="0.0" ixz="0.0" iyy="0.0010000000474974513" iyz="0.0" izz="0.0010000000474974513"/>
    </inertial>
    <visual name="SM_r_hand_ring_3_visual_0">
      <origin xyz="0.0 0.0 0.0" rpy="3.1415927410125732 0.0 3.1415927410125732"/>
      <geometry>
        <mesh filename="file://iCub/meshes/stl/full_RightRing3.stl" scale="1.0 1.0 1.0"/>
      </geometry>
      <material name="SM_r_hand_ring_3_visual_0_material">
        <color rgba="0.9 0.9 0.9 1.0"/>
      </material>
    </visual>
  </link>
  <joint name="r_hand_ring_tip_joint" type="fixed">
    <origin xyz="0.0168 0.0 0.0" rpy="-1.5707963705062866 0.0 0.0"/>
    <parent link="r_hand_ring_3"/>
    <child link="r_hand_ring_tip"/>
  </joint>
  <link name="r_hand_ring_tip">
    <inertial>
      <origin xyz="0.0 0.0 0.0" rpy="0.0 0.0 0.0"/>
      <mass value="0.0"/>
      <inertia ixx="0.0" ixy="0.0" ixz="0.0" iyy="0.0" iyz="0.0" izz="0.0"/>
    </inertial>
  </link>
  <joint name="r_hand_little_0_joint" type="revolute">
    <origin xyz="-0.06362900137901306 0.004443199839442968 -0.010110927745699883" rpy="-1.547965407371521 -0.15434306859970093 3.0537750720977783"/>
    <axis xyz="0.0 0.0 1.0"/>
    <parent link="r_hand"/>
    <child link="r_hand_little_0"/>
    <limit effort="50000.0" lower="0.0" upper="0.3490658402442932" velocity="50000.0"/>
  </joint>
  <link name="r_hand_little_0">
    <inertial>
      <origin xyz="0.0 0.0 0.0" rpy="0.0 0.0 0.0"/>
      <mass value="0.009999999776482582"/>
      <inertia ixx="0.0010000000474974513" ixy="0.0" ixz="0.0" iyy="0.0010000000474974513" iyz="0.0" izz="0.0010000000474974513"/>
    </inertial>
    <visual name="SM_r_hand_little_0_visual_0">
      <origin xyz="0.0 0.0 0.003800000064074993" rpy="0.0 0.0 0.0"/>
      <geometry>
        <mesh filename="file://iCub/meshes/stl/full_RightLittle0.stl" scale="1.0 1.0 1.0"/>
      </geometry>
      <material name="SM_r_hand_little_0_visual_0_material">
        <color rgba="0.9 0.9 0.9 1.0"/>
      </material>
    </visual>
  </link>
  <joint name="r_hand_little_1_joint" type="revolute">
    <origin xyz="0.014800000004470348 -0.0017500000540167093 1.0715659546529912e-19" rpy="1.5707963705062866 0.0 0.0"/>
    <axis xyz="0.0 0.0 1.0"/>
    <parent link="r_hand_little_0"/>
    <child link="r_hand_little_1"/>
    <limit effort="50000.0" lower="0.0" upper="1.5707963705062866" velocity="50000.0"/>
  </joint>
  <link name="r_hand_little_1">
    <inertial>
      <origin xyz="0.0 0.0 0.0" rpy="0.0 0.0 0.0"/>
      <mass value="0.009999999776482582"/>
      <inertia ixx="0.0010000000474974513" ixy="0.0" ixz="0.0" iyy="0.0010000000474974513" iyz="0.0" izz="0.0010000000474974513"/>
    </inertial>
    <visual name="SM_r_hand_little_1_visual_0">
      <origin xyz="0.0 0.0 0.0" rpy="3.1415927410125732 0.0 0.0"/>
      <geometry>
        <mesh filename="file://iCub/meshes/stl/full_RightLittle1.stl" scale="1.0 1.0 1.0"/>
      </geometry>
      <material name="SM_r_hand_little_1_visual_0_material">
        <color rgba="0.9 0.9 0.9 1.0"/>
      </material>
    </visual>
  </link>
  <joint name="r_hand_little_2_joint" type="revolute">
    <origin xyz="0.021900000050663948 0.0 0.0" rpy="0.0 0.0 0.0"/>
    <axis xyz="0.0 0.0 1.0"/>
    <parent link="r_hand_little_1"/>
    <child link="r_hand_little_2"/>
    <limit effort="50000.0" lower="0.0" upper="1.5707963705062866" velocity="50000.0"/>
  </joint>
  <link name="r_hand_little_2">
    <inertial>
      <origin xyz="0.0 0.0 0.0" rpy="0.0 0.0 0.0"/>
      <mass value="0.009999999776482582"/>
      <inertia ixx="0.0010000000474974513" ixy="0.0" ixz="0.0" iyy="0.0010000000474974513" iyz="0.0" izz="0.0010000000474974513"/>
    </inertial>
    <visual name="SM_r_hand_little_2_visual_0">
      <origin xyz="0.0 0.0 0.0" rpy="3.1415927410125732 0.0 0.0"/>
      <geometry>
        <mesh filename="file://iCub/meshes/stl/full_RightLittle2.stl" scale="1.0 1.0 1.0"/>
      </geometry>
      <material name="SM_r_hand_little_2_visual_0_material">
        <color rgba="0.9 0.9 0.9 1.0"/>
      </material>
    </visual>
  </link>
  <joint name="r_hand_little_3_joint" type="revolute">
    <origin xyz="0.01899999938905239 0.0 0.0" rpy="0.0 0.0 0.0"/>
    <axis xyz="0.0 0.0 1.0"/>
    <parent link="r_hand_little_2"/>
    <child link="r_hand_little_3"/>
    <limit effort="50000.0" lower="0.0" upper="1.5707963705062866" velocity="50000.0"/>
  </joint>
  <link name="r_hand_little_3">
    <inertial>
      <origin xyz="0.0 0.0 0.0" rpy="0.0 0.0 0.0"/>
      <mass value="0.009999999776482582"/>
      <inertia ixx="0.0010000000474974513" ixy="0.0" ixz="0.0" iyy="0.0010000000474974513" iyz="0.0" izz="0.0010000000474974513"/>
    </inertial>
    <visual name="SM_r_hand_little_3_visual_0">
      <origin xyz="0.0 0.0 0.0" rpy="3.1415927410125732 0.0 3.1415927410125732"/>
      <geometry>
        <mesh filename="file://iCub/meshes/stl/full_RightLittle3.stl" scale="1.0 1.0 1.0"/>
      </geometry>
      <material name="SM_r_hand_little_3_visual_0_material">
        <color rgba="0.9 0.9 0.9 1.0"/>
      </material>
    </visual>
  </link>
  <joint name="r_hand_little_tip_joint" type="fixed">
    <origin xyz="0.0168 0.0 0.0" rpy="-1.5707963705062866 0.0 0.0"/>
    <parent link="r_hand_little_3"/>
    <child link="r_hand_little_tip"/>
  </joint>
  <link name="r_hand_little_tip">
    <inertial>
      <origin xyz="0.0 0.0 0.0" rpy="0.0 0.0 0.0"/>
      <mass value="0.0"/>
      <inertia ixx="0.0" ixy="0.0" ixz="0.0" iyy="0.0" iyz="0.0" izz="0.0"/>
    </inertial>
  </link>
  <joint name="r_gripper_tool_frame_joint" type="fixed">
    <origin xyz="0.0 0.0 0.13" rpy="0.0 0.0 0.0"/>
    <parent link="r_hand"/>
    <child link="r_gripper_tool_frame"/>
  </joint>
  <link name="r_gripper_tool_frame">
    <inertial>
      <origin xyz="0.0 0.0 0.0" rpy="0.0 0.0 0.0"/>
      <mass value="0.10000000149011612"/>
      <inertia ixx="0.009999999776482582" ixy="0.0" ixz="0.0" iyy="0.009999999776482582" iyz="0.0" izz="0.009999999776482582"/>
    </inertial>
  </link>
  <joint name="l_shoulder_pitch" type="revolute">
    <origin xyz="-0.02083509974181652 0.03974229842424393 0.10520289838314056" rpy="0.25326162576675415 -1.1977334679613705e-07 -0.26179930567741394"/>
    <axis xyz="3.323079909023363e-07 1.0 1.4452224661454238e-07"/>
    <parent link="chest"/>
    <child link="l_shoulder_1"/>
    <limit effort="50000.0" lower="-3.054326295852661" upper="0.3490658402442932" velocity="120.0"/>
  </joint>
  <link name="l_shoulder_1">
    <inertial>
      <origin xyz="0.00016753510863054544 0.08722598105669022 0.00045078765833750367" rpy="2.3835556507110596 0.6763865351676941 0.7877201437950134"/>
      <mass value="0.7864400148391724"/>
      <inertia ixx="0.009740694426000118" ixy="0.0" ixz="0.0" iyy="0.01004073116928339" iyz="0.0" izz="0.010218574665486813"/>
    </inertial>
    <visual name="SM_l_shoulder_1_visual_0">
      <origin xyz="0.03041122294962406 -0.029140478000044823 0.0190957672894001" rpy="-0.06688748300075531 -0.24445247650146484 -1.3007776737213135"/>
      <geometry>
        <mesh filename="file://iCub/meshes/stl/sim_icub3_l_shoulder_1_prt.stl" scale="0.0010000000474974513 0.0010000000474974513 0.0010000000474974513"/>
      </geometry>
      <material name="SM_l_shoulder_1_visual_0_material">
        <color rgba="0.9 0.9 0.9 1.0"/>
      </material>
    </visual>
  </link>
  <joint name="l_shoulder_roll" type="revolute">
    <origin xyz="0.004992849193513393 0.1114998385310173 0.00026865024119615555" rpy="-0.1745329648256302 -0.053747598081827164 0.0"/>
    <axis xyz="0.9999998211860657 2.034825286045816e-07 -4.023022981414215e-08"/>
    <parent link="l_shoulder_1"/>
    <child link="l_shoulder_2"/>
    <limit effort="50000.0" lower="0.20943951606750488" upper="2.8448867797851562" velocity="120.0"/>
  </joint>
  <link name="l_shoulder_2">
    <inertial>
      <origin xyz="0.007668668869882822 0.00018849980551749468 -0.020403454080224037" rpy="0.4195014238357544 -0.8761745691299438 1.9819856882095337"/>
      <mass value="0.424919992685318"/>
      <inertia ixx="0.009873848408460617" ixy="0.0" ixz="0.0" iyy="0.01004764437675476" iyz="0.0" izz="0.010078507475554943"/>
    </inertial>
    <visual name="SM_l_shoulder_2_visual_0">
      <origin xyz="0.026393096894025803 -0.14064030349254608 0.017434481531381607" rpy="-0.12008543312549591 -0.22978873550891876 -1.2882781028747559"/>
      <geometry>
        <mesh filename="file://iCub/meshes/stl/sim_icub3_l_shoulder_2_prt.stl" scale="0.0010000000474974513 0.0010000000474974513 0.0010000000474974513"/>
      </geometry>
      <material name="SM_l_shoulder_2_visual_0_material">
        <color rgba="0.9 0.9 0.9 1.0"/>
      </material>
    </visual>
  </link>
  <joint name="l_shoulder_3_joint" type="fixed">
    <origin xyz="-0.004350133156978318 3.632573233602887e-07 -0.05430003872406172" rpy="0.0 0.0 0.0"/>
    <parent link="l_shoulder_2"/>
    <child link="l_shoulder_3"/>
  </joint>
  <link name="l_shoulder_3">
    <inertial>
      <origin xyz="-9.561931801727042e-05 3.089115125476383e-05 -0.007966608740389347" rpy="2.6417977809906006 -0.8177776336669922 -1.9379992485046387"/>
      <mass value="0.26249998807907104"/>
      <inertia ixx="0.009988517500460148" ixy="0.0" ixz="0.0" iyy="0.009998632594943047" iyz="0.0" izz="0.010012850165367126"/>
    </inertial>
    <visual name="SM_l_shoulder_3_visual_0">
      <origin xyz="0.030743230134248734 -0.14064067602157593 0.07173451781272888" rpy="-0.12008543312549591 -0.22978873550891876 -1.2882781028747559"/>
      <geometry>
        <mesh filename="file://iCub/meshes/stl/sim_icub3_l_shoulder_3_prt.stl" scale="0.0010000000474974513 0.0010000000474974513 0.0010000000474974513"/>
      </geometry>
      <material name="SM_l_shoulder_3_visual_0_material">
        <color rgba="0.9 0.9 0.9 1.0"/>
      </material>
    </visual>
  </link>
  <joint name="l_shoulder_yaw" type="revolute">
    <origin xyz="0.0 -4.2345249084974057e-07 -0.022499941289424896" rpy="0.0 0.0 0.0"/>
    <axis xyz="2.2276473998772417e-08 -4.3937863125620424e-08 -1.000000238418579"/>
    <parent link="l_shoulder_3"/>
    <child link="l_upper_arm"/>
    <limit effort="50000.0" lower="-0.8726646304130554" upper="1.3962633609771729" velocity="120.0"/>
  </joint>
  <link name="l_upper_arm">
    <inertial>
      <origin xyz="0.0010476375464349985 0.0025596225168555975 -0.05065314844250679" rpy="0.6258816123008728 -1.3060826063156128 -2.6123416423797607"/>
      <mass value="1.6772899627685547"/>
      <inertia ixx="0.0012748966692015529" ixy="0.0" ixz="0.0" iyy="0.0029882946982979774" iyz="0.0" izz="0.0031005386263132095"/>
    </inertial>
    <visual name="SM_l_upper_arm_visual_0">
      <origin xyz="0.030743148177862167 -0.1406402438879013 0.09423445910215378" rpy="-0.12008543312549591 -0.22978873550891876 -1.2882781028747559"/>
      <geometry>
        <mesh filename="file://iCub/meshes/stl/sim_icub3_l_upperarm_prt.stl" scale="0.0010000000474974513 0.0010000000474974513 0.0010000000474974513"/>
      </geometry>
      <material name="SM_l_upper_arm_visual_0_material">
        <color rgba="0.3 0.3 0.3 1.0"/>
      </material>
    </visual>
  </link>
  <joint name="l_elbow" type="revolute">
    <origin xyz="0.009999929927289486 -0.0014996473910287023 -0.1237003356218338" rpy="0.0 0.0 0.0"/>
    <axis xyz="-8.811824159238313e-08 -1.000000238418579 4.4047361313914735e-08"/>
    <parent link="l_upper_arm"/>
    <child link="l_elbow_1"/>
    <limit effort="50000.0" lower="-0.05235987901687622" upper="1.3089969158172607" velocity="120.0"/>
  </joint>
  <link name="l_elbow_1">
    <inertial>
      <origin xyz="-0.009947434067726135 0.0004713243688456714 -0.01488945446908474" rpy="-0.28436723351478577 0.8652978539466858 -1.8368686437606812"/>
      <mass value="0.22160999476909637"/>
      <inertia ixx="0.009974990040063858" ixy="0.0" ixz="0.0" iyy="0.010000604204833508" iyz="0.0" izz="0.010024406015872955"/>
    </inertial>
    <visual name="SM_l_elbow_1_visual_0">
      <origin xyz="0.020743217319250107 -0.13914059102535248 0.21793480217456818" rpy="-0.12008543312549591 -0.22978873550891876 -1.2882781028747559"/>
      <geometry>
        <mesh filename="file://iCub/meshes/stl/sim_icub3_l_elbow_1_prt.stl" scale="0.0010000000474974513 0.0010000000474974513 0.0010000000474974513"/>
      </geometry>
      <material name="SM_l_elbow_1_visual_0_material">
        <color rgba="0.3 0.3 0.3 1.0"/>
      </material>
    </visual>
  </link>
  <joint name="l_wrist_prosup" type="revolute">
    <origin xyz="-0.014999870210886002 0.001999643398448825 -0.055300064384937286" rpy="0.0 0.0 0.0"/>
    <axis xyz="2.2276473998772417e-08 -4.3937863125620424e-08 -1.000000238418579"/>
    <parent link="l_elbow_1"/>
    <child link="l_forearm"/>
    <limit effort="50000.0" lower="-1.535889744758606" upper="1.535889744758606" velocity="120.0"/>
  </joint>
  <link name="l_forearm">
    <inertial>
      <origin xyz="-0.006323186680674553 -4.644477303372696e-05 -0.030456749722361565" rpy="-2.150003433227539 -1.083567500114441 0.06833469867706299"/>
      <mass value="0.8731099963188171"/>
      <inertia ixx="0.0006055216654203832" ixy="0.0" ixz="0.0" iyy="0.0012594523141160607" iyz="0.0" izz="0.0012795031070709229"/>
    </inertial>
    <visual name="SM_l_forearm_visual_0">
      <origin xyz="0.03574308753013611 -0.14114023745059967 0.27323487401008606" rpy="-0.12008543312549591 -0.22978873550891876 -1.2882781028747559"/>
      <geometry>
        <mesh filename="file://iCub/meshes/stl/sim_icub3_l_forearm_prt.stl" scale="0.0010000000474974513 0.0010000000474974513 0.0010000000474974513"/>
      </geometry>
      <material name="SM_l_forearm_visual_0_material">
        <color rgba="0.3 0.3 0.3 1.0"/>
      </material>
    </visual>
  </link>
  <joint name="l_wrist_pitch" type="revolute">
    <origin xyz="0.01660001650452614 0.0020068951416760683 -0.10749964416027069" rpy="0.0 0.0 0.0"/>
    <axis xyz="-0.9999998211860657 -2.034825286045816e-07 4.023022981414215e-08"/>
    <parent link="l_forearm"/>
    <child link="l_wrist_1"/>
    <limit effort="50000.0" lower="-1.2217304706573486" upper="0.4363323152065277" velocity="120.0"/>
  </joint>
  <link name="l_wrist_1">
    <inertial>
      <origin xyz="-0.014340376481413841 -0.000501620233990252 -0.00011512600758578628" rpy="1.5575261116027832 0.3207107186317444 -1.0782119035720825"/>
      <mass value="0.03318300098180771"/>
      <inertia ixx="0.009999112226068974" ixy="0.0" ixz="0.0" iyy="0.009999994188547134" iyz="0.0" izz="0.010000893846154213"/>
    </inertial>
    <visual name="SM_l_wrist_1_visual_0">
      <origin xyz="0.01914307288825512 -0.14314714074134827 0.38073450326919556" rpy="-0.12008543312549591 -0.22978873550891876 -1.2882781028747559"/>
      <geometry>
        <mesh filename="file://iCub/meshes/stl/sim_icub3_l_wrist_1_prt.stl" scale="0.0010000000474974513 0.0010000000474974513 0.0010000000474974513"/>
      </geometry>
      <material name="SM_l_wrist_1_visual_0_material">
        <color rgba="0.9 0.9 0.9 1.0"/>
      </material>
    </visual>
  </link>
  <joint name="l_wrist_yaw" type="revolute">
    <origin xyz="-0.0006341065163724124 -0.019499899819493294 0.0023665183689445257" rpy="0.0 1.5707963705062866 0.0"/>
    <axis xyz="-2.220446049250313e-16 1.0 0.0"/>
    <parent link="l_wrist_1"/>
    <child link="l_hand"/>
    <limit effort="50000.0" lower="-0.3490658402442932" upper="0.4363323152065277" velocity="50000.0"/>
  </joint>
  <link name="l_hand">
    <inertial>
      <origin xyz="0.06476802378892899 0.0056304000318050385 0.02266022004187107" rpy="-3.090332269668579 -0.7698649168014526 -0.5445988178253174"/>
      <mass value="0.24780599772930145"/>
      <inertia ixx="0.00995639432221651" ixy="0.0" ixz="0.0" iyy="0.010002526454627514" iyz="0.0" izz="0.01004108041524887"/>
    </inertial>
    <visual name="SM_l_hand_visual_0">
      <origin xyz="-0.0027160674799233675 -0.0015567999798804522 -0.0024823539424687624" rpy="1.5707963705062866 -0.26179930567741394 3.3224480235523256e-17"/>
      <geometry>
        <mesh filename="file://iCub/meshes/stl/full_LeftHandPalm.stl" scale="1.0 1.0 1.0"/>
      </geometry>
      <material name="SM_l_hand_visual_0_material">
        <color rgba="0.9 0.9 0.9 1.0"/>
      </material>
    </visual>
    <visual name="SM_l_hand_visual_1">
      <origin xyz="0.05765429884195328 -0.005556799937039614 0.013693831861019135" rpy="-1.5707963705062866 -0.26179930567741394 5.746937229130156e-17"/>
      <geometry>
        <mesh filename="file://iCub/meshes/stl/full_LeftTopCover.stl" scale="1.0 1.0 1.0"/>
      </geometry>
      <material name="SM_l_hand_visual_1_material">
        <color rgba="0.9 0.9 0.9 1.0"/>
      </material>
    </visual>
  </link>
  <joint name="l_gripper_tool_frame_joint" type="fixed">
    <origin xyz="0.0 0.0 0.13" rpy="0.0 0.0 0.0"/>
    <parent link="l_hand"/>
    <child link="l_gripper_tool_frame"/>
  </joint>
  <link name="l_gripper_tool_frame">
    <inertial>
      <origin xyz="0.0 0.0 0.0" rpy="0.0 0.0 0.0"/>
      <mass value="0.10000000149011612"/>
      <inertia ixx="0.009999999776482582" ixy="0.0" ixz="0.0" iyy="0.009999999776482582" iyz="0.0" izz="0.009999999776482582"/>
    </inertial>
  </link>
  <joint name="l_hand_thumb_0_joint" type="revolute">
    <origin xyz="0.0318492129445076 -0.004056800156831741 0.019202696159482002" rpy="3.0535080432891846 -1.3239694833755493 0.16574880480766296"/>
    <axis xyz="0.0 0.0 1.0"/>
    <parent link="l_hand"/>
    <child link="l_hand_thumb_0"/>
    <limit effort="50000.0" lower="0.0" upper="1.5707963705062866" velocity="50000.0"/>
  </joint>
  <link name="l_hand_thumb_0">
    <inertial>
      <origin xyz="0.0 0.0 0.0" rpy="0.0 0.0 0.0"/>
      <mass value="0.009999999776482582"/>
      <inertia ixx="0.0010000000474974513" ixy="0.0" ixz="0.0" iyy="0.0010000000474974513" iyz="0.0" izz="0.0010000000474974513"/>
    </inertial>
    <visual name="SM_l_hand_thumb_0_visual_0">
      <origin xyz="0.0 0.0 0.0" rpy="3.1415927410125732 0.0 0.0"/>
      <geometry>
        <mesh filename="file://iCub/meshes/stl/full_LeftThumb0.stl" scale="1.0 1.0 1.0"/>
      </geometry>
      <material name="SM_l_hand_thumb_0_visual_0_material">
        <color rgba="0.9 0.9 0.9 1.0"/>
      </material>
    </visual>
  </link>
  <joint name="l_hand_thumb_1_joint" type="revolute">
    <origin xyz="0.0210999995470047 0.004900000058114529 -3.0003846730283755e-19" rpy="1.5707963705062866 0.0 0.0"/>
    <axis xyz="0.0 0.0 1.0"/>
    <parent link="l_hand_thumb_0"/>
    <child link="l_hand_thumb_1"/>
    <limit effort="50000.0" lower="0.0" upper="1.5707963705062866" velocity="50000.0"/>
  </joint>
  <link name="l_hand_thumb_1">
    <inertial>
      <origin xyz="0.0 0.0 0.0" rpy="0.0 0.0 0.0"/>
      <mass value="0.009999999776482582"/>
      <inertia ixx="0.0010000000474974513" ixy="0.0" ixz="0.0" iyy="0.0010000000474974513" iyz="0.0" izz="0.0010000000474974513"/>
    </inertial>
    <visual name="SM_l_hand_thumb_1_visual_0">
      <origin xyz="0.0 0.0 0.0" rpy="3.1415927410125732 0.0 3.1415927410125732"/>
      <geometry>
        <mesh filename="file://iCub/meshes/stl/full_LeftThumb1.stl" scale="1.0 1.0 1.0"/>
      </geometry>
      <material name="SM_l_hand_thumb_1_visual_0_material">
        <color rgba="0.9 0.9 0.9 1.0"/>
      </material>
    </visual>
  </link>
  <joint name="l_hand_thumb_2_joint" type="revolute">
    <origin xyz="0.026000000536441803 0.0 0.0" rpy="0.0 0.0 0.0"/>
    <axis xyz="0.0 0.0 1.0"/>
    <parent link="l_hand_thumb_1"/>
    <child link="l_hand_thumb_2"/>
    <limit effort="50000.0" lower="0.0" upper="1.5707963705062866" velocity="50000.0"/>
  </joint>
  <link name="l_hand_thumb_2">
    <inertial>
      <origin xyz="0.0 0.0 0.0" rpy="0.0 0.0 0.0"/>
      <mass value="0.009999999776482582"/>
      <inertia ixx="0.0010000000474974513" ixy="0.0" ixz="0.0" iyy="0.0010000000474974513" iyz="0.0" izz="0.0010000000474974513"/>
    </inertial>
    <visual name="SM_l_hand_thumb_2_visual_0">
      <origin xyz="0.0 0.0 0.0" rpy="0.0 0.0 3.1415927410125732"/>
      <geometry>
        <mesh filename="file://iCub/meshes/stl/full_LeftThumb2.stl" scale="1.0 1.0 1.0"/>
      </geometry>
      <material name="SM_l_hand_thumb_2_visual_0_material">
        <color rgba="0.9 0.9 0.9 1.0"/>
      </material>
    </visual>
  </link>
  <joint name="l_hand_thumb_3_joint" type="revolute">
    <origin xyz="0.02199999988079071 0.0 0.0" rpy="0.0 0.0 0.0"/>
    <axis xyz="0.0 0.0 1.0"/>
    <parent link="l_hand_thumb_2"/>
    <child link="l_hand_thumb_3"/>
    <limit effort="50000.0" lower="0.0" upper="1.5707963705062866" velocity="50000.0"/>
  </joint>
  <link name="l_hand_thumb_3">
    <inertial>
      <origin xyz="0.0 0.0 0.0" rpy="0.0 0.0 0.0"/>
      <mass value="0.009999999776482582"/>
      <inertia ixx="0.0010000000474974513" ixy="0.0" ixz="0.0" iyy="0.0010000000474974513" iyz="0.0" izz="0.0010000000474974513"/>
    </inertial>
    <visual name="SM_l_hand_thumb_3_visual_0">
      <origin xyz="0.0 0.0 0.0" rpy="0.0 3.1415927410125732 0.0"/>
      <geometry>
        <mesh filename="file://iCub/meshes/stl/full_LeftThumb3.stl" scale="1.0 1.0 1.0"/>
      </geometry>
      <material name="SM_l_hand_thumb_3_visual_0_material">
        <color rgba="0.9 0.9 0.9 1.0"/>
      </material>
    </visual>
  </link>
  <joint name="l_hand_thumb_tip_joint" type="fixed">
    <origin xyz="0.0168 0.0 0.0" rpy="-1.5707963705062866 0.0 0.0"/>
    <parent link="l_hand_thumb_3"/>
    <child link="l_hand_thumb_tip"/>
  </joint>
  <link name="l_hand_thumb_tip">
    <inertial>
      <origin xyz="0.0 0.0 0.0" rpy="0.0 0.0 0.0"/>
      <mass value="0.0"/>
      <inertia ixx="0.0" ixy="0.0" ixz="0.0" iyy="0.0" iyz="0.0" izz="0.0"/>
    </inertial>
  </link>
  <joint name="l_hand_index_0_joint" type="revolute">
    <origin xyz="0.05255843326449394 0.005143200047314167 0.039473339915275574" rpy="-1.4815961122512817 -2.8085129261016846 3.1349987983703613"/>
    <axis xyz="0.0 0.0 -1.0"/>
    <parent link="l_hand"/>
    <child link="l_hand_index_0"/>
    <limit effort="50000.0" lower="-0.3490658402442932" upper="0.0" velocity="50000.0"/>
  </joint>
  <link name="l_hand_index_0">
    <inertial>
      <origin xyz="0.0 0.0 0.0" rpy="0.0 0.0 0.0"/>
      <mass value="0.009999999776482582"/>
      <inertia ixx="0.0010000000474974513" ixy="0.0" ixz="0.0" iyy="0.0010000000474974513" iyz="0.0" izz="0.0010000000474974513"/>
    </inertial>
    <visual name="SM_l_hand_index_0_visual_0">
      <origin xyz="0.0 0.0 0.0" rpy="0.0 0.0 0.0"/>
      <geometry>
        <mesh filename="file://iCub/meshes/stl/full_LeftIndex0.stl" scale="1.0 1.0 1.0"/>
      </geometry>
      <material name="SM_l_hand_index_0_visual_0_material">
        <color rgba="0.9 0.9 0.9 1.0"/>
      </material>
    </visual>
  </link>
  <joint name="l_hand_index_1_joint" type="revolute">
    <origin xyz="0.014800000004470348 -0.0017500000540167093 1.0715659546529912e-19" rpy="1.5707963705062866 0.0 0.0"/>
    <axis xyz="0.0 0.0 1.0"/>
    <parent link="l_hand_index_0"/>
    <child link="l_hand_index_1"/>
    <limit effort="50000.0" lower="0.0" upper="1.5707963705062866" velocity="50000.0"/>
  </joint>
  <link name="l_hand_index_1">
    <inertial>
      <origin xyz="0.0 0.0 0.0" rpy="0.0 0.0 0.0"/>
      <mass value="0.009999999776482582"/>
      <inertia ixx="0.0010000000474974513" ixy="0.0" ixz="0.0" iyy="0.0010000000474974513" iyz="0.0" izz="0.0010000000474974513"/>
    </inertial>
    <visual name="SM_l_hand_index_1_visual_0">
      <origin xyz="0.0 0.0 0.0" rpy="0.0 0.0 3.1415927410125732"/>
      <geometry>
        <mesh filename="file://iCub/meshes/stl/full_LeftIndex1.stl" scale="1.0 1.0 1.0"/>
      </geometry>
      <material name="SM_l_hand_index_1_visual_0_material">
        <color rgba="0.9 0.9 0.9 1.0"/>
      </material>
    </visual>
  </link>
  <joint name="l_hand_index_2_joint" type="revolute">
    <origin xyz="0.02590000070631504 0.0 0.0" rpy="0.0 0.0 0.0"/>
    <axis xyz="0.0 0.0 1.0"/>
    <parent link="l_hand_index_1"/>
    <child link="l_hand_index_2"/>
    <limit effort="50000.0" lower="0.0" upper="1.5707963705062866" velocity="50000.0"/>
  </joint>
  <link name="l_hand_index_2">
    <inertial>
      <origin xyz="0.0 0.0 0.0" rpy="0.0 0.0 0.0"/>
      <mass value="0.009999999776482582"/>
      <inertia ixx="0.0010000000474974513" ixy="0.0" ixz="0.0" iyy="0.0010000000474974513" iyz="0.0" izz="0.0010000000474974513"/>
    </inertial>
    <visual name="SM_l_hand_index_2_visual_0">
      <origin xyz="0.0 0.0 0.0" rpy="0.0 0.0 3.1415927410125732"/>
      <geometry>
        <mesh filename="file://iCub/meshes/stl/full_LeftIndex2.stl" scale="1.0 1.0 1.0"/>
      </geometry>
      <material name="SM_l_hand_index_2_visual_0_material">
        <color rgba="0.9 0.9 0.9 1.0"/>
      </material>
    </visual>
  </link>
  <joint name="l_hand_index_3_joint" type="revolute">
    <origin xyz="0.02199999988079071 0.0 0.0" rpy="0.0 0.0 0.0"/>
    <axis xyz="0.0 0.0 1.0"/>
    <parent link="l_hand_index_2"/>
    <child link="l_hand_index_3"/>
    <limit effort="50000.0" lower="0.0" upper="1.5707963705062866" velocity="50000.0"/>
  </joint>
  <link name="l_hand_index_3">
    <inertial>
      <origin xyz="0.0 0.0 0.0" rpy="0.0 0.0 0.0"/>
      <mass value="0.009999999776482582"/>
      <inertia ixx="0.0010000000474974513" ixy="0.0" ixz="0.0" iyy="0.0010000000474974513" iyz="0.0" izz="0.0010000000474974513"/>
    </inertial>
    <visual name="SM_l_hand_index_3_visual_0">
      <origin xyz="0.0 0.0 0.0" rpy="3.1415927410125732 0.0 3.1415927410125732"/>
      <geometry>
        <mesh filename="file://iCub/meshes/stl/full_LeftIndex3.stl" scale="1.0 1.0 1.0"/>
      </geometry>
      <material name="SM_l_hand_index_3_visual_0_material">
        <color rgba="0.9 0.9 0.9 1.0"/>
      </material>
    </visual>
  </link>
  <joint name="l_hand_index_tip_joint" type="fixed">
    <origin xyz="0.0168 0.0 0.0" rpy="-1.5707963705062866 0.0 0.0"/>
    <parent link="l_hand_index_3"/>
    <child link="l_hand_index_tip"/>
  </joint>
  <link name="l_hand_index_tip">
    <inertial>
      <origin xyz="0.0 0.0 0.0" rpy="0.0 0.0 0.0"/>
      <mass value="0.0"/>
      <inertia ixx="0.0" ixy="0.0" ixz="0.0" iyy="0.0" iyz="0.0" izz="0.0"/>
    </inertial>
  </link>
  <joint name="l_hand_middle_0_joint" type="revolute">
    <origin xyz="0.05754045024514198 0.0060431999154388905 0.023777974769473076" rpy="1.5707963705062866 -0.26179930567741394 3.437404952873515e-17"/>
    <axis xyz="0.0 0.0 1.0"/>
    <parent link="l_hand"/>
    <child link="l_hand_middle_0"/>
    <limit effort="50000.0" lower="0.0" upper="0.3490658402442932" velocity="50000.0"/>
  </joint>
  <link name="l_hand_middle_0">
    <inertial>
      <origin xyz="0.0 0.0 0.0" rpy="0.0 0.0 0.0"/>
      <mass value="0.009999999776482582"/>
      <inertia ixx="0.0010000000474974513" ixy="0.0" ixz="0.0" iyy="0.0010000000474974513" iyz="0.0" izz="0.0010000000474974513"/>
    </inertial>
    <visual name="SM_l_hand_middle_0_visual_0">
      <origin xyz="0.0 0.0 0.0" rpy="3.1415927410125732 0.0 1.5707963705062866"/>
      <geometry>
        <mesh filename="file://iCub/meshes/stl/full_LeftMiddle0.stl" scale="1.0 1.0 1.0"/>
      </geometry>
      <material name="SM_l_hand_middle_0_visual_0_material">
        <color rgba="0.9 0.9 0.9 1.0"/>
      </material>
    </visual>
  </link>
  <joint name="l_hand_middle_1_joint" type="revolute">
    <origin xyz="0.015300000086426735 -0.002199999988079071 1.3471114489217688e-19" rpy="1.5707963705062866 0.0 0.0"/>
    <axis xyz="0.0 0.0 1.0"/>
    <parent link="l_hand_middle_0"/>
    <child link="l_hand_middle_1"/>
    <limit effort="50000.0" lower="0.0" upper="1.5707963705062866" velocity="50000.0"/>
  </joint>
  <link name="l_hand_middle_1">
    <inertial>
      <origin xyz="0.0 0.0 0.0" rpy="0.0 0.0 0.0"/>
      <mass value="0.009999999776482582"/>
      <inertia ixx="0.0010000000474974513" ixy="0.0" ixz="0.0" iyy="0.0010000000474974513" iyz="0.0" izz="0.0010000000474974513"/>
    </inertial>
    <visual name="SM_l_hand_middle_1_visual_0">
      <origin xyz="0.0 0.0 0.0" rpy="0.0 0.0 3.1415927410125732"/>
      <geometry>
        <mesh filename="file://iCub/meshes/stl/full_LeftMiddle1.stl" scale="1.0 1.0 1.0"/>
      </geometry>
      <material name="SM_l_hand_middle_1_visual_0_material">
        <color rgba="0.9 0.9 0.9 1.0"/>
      </material>
    </visual>
  </link>
  <joint name="l_hand_middle_2_joint" type="revolute">
    <origin xyz="0.025800000876188278 0.0 0.0" rpy="0.0 0.0 0.0"/>
    <axis xyz="0.0 0.0 1.0"/>
    <parent link="l_hand_middle_1"/>
    <child link="l_hand_middle_2"/>
    <limit effort="50000.0" lower="0.0" upper="1.5707963705062866" velocity="50000.0"/>
  </joint>
  <link name="l_hand_middle_2">
    <inertial>
      <origin xyz="0.0 0.0 0.0" rpy="0.0 0.0 0.0"/>
      <mass value="0.009999999776482582"/>
      <inertia ixx="0.0010000000474974513" ixy="0.0" ixz="0.0" iyy="0.0010000000474974513" iyz="0.0" izz="0.0010000000474974513"/>
    </inertial>
    <visual name="SM_l_hand_middle_2_visual_0">
      <origin xyz="0.0 0.0 0.0" rpy="0.0 0.0 3.1415927410125732"/>
      <geometry>
        <mesh filename="file://iCub/meshes/stl/full_LeftMiddle2.stl" scale="1.0 1.0 1.0"/>
      </geometry>
      <material name="SM_l_hand_middle_2_visual_0_material">
        <color rgba="0.9 0.9 0.9 1.0"/>
      </material>
    </visual>
  </link>
  <joint name="l_hand_middle_3_joint" type="revolute">
    <origin xyz="0.024000000208616257 0.0 0.0" rpy="0.0 0.0 0.0"/>
    <axis xyz="0.0 0.0 1.0"/>
    <parent link="l_hand_middle_2"/>
    <child link="l_hand_middle_3"/>
    <limit effort="50000.0" lower="0.0" upper="1.5707963705062866" velocity="50000.0"/>
  </joint>
  <link name="l_hand_middle_3">
    <inertial>
      <origin xyz="0.0 0.0 0.0" rpy="0.0 0.0 0.0"/>
      <mass value="0.009999999776482582"/>
      <inertia ixx="0.0010000000474974513" ixy="0.0" ixz="0.0" iyy="0.0010000000474974513" iyz="0.0" izz="0.0010000000474974513"/>
    </inertial>
    <visual name="SM_l_hand_middle_3_visual_0">
      <origin xyz="0.0 0.0 0.0" rpy="0.0 0.0 3.1415927410125732"/>
      <geometry>
        <mesh filename="file://iCub/meshes/stl/full_LeftMiddle3.stl" scale="1.0 1.0 1.0"/>
      </geometry>
      <material name="SM_l_hand_middle_3_visual_0_material">
        <color rgba="0.9 0.9 0.9 1.0"/>
      </material>
    </visual>
  </link>
  <joint name="l_hand_middle_tip_joint" type="fixed">
    <origin xyz="0.0168 0.0 0.0" rpy="-1.5707963705062866 0.0 0.0"/>
    <parent link="l_hand_middle_3"/>
    <child link="l_hand_middle_tip"/>
  </joint>
  <link name="l_hand_middle_tip">
    <inertial>
      <origin xyz="0.0 0.0 0.0" rpy="0.0 0.0 0.0"/>
      <mass value="0.0"/>
      <inertia ixx="0.0" ixy="0.0" ixz="0.0" iyy="0.0" iyz="0.0" izz="0.0"/>
    </inertial>
  </link>
  <joint name="l_hand_ring_0_joint" type="revolute">
    <origin xyz="0.06069108471274376 0.0054432000033557415 0.008658226579427719" rpy="-1.547965407371521 -2.9872496128082275 3.0537750720977783"/>
    <axis xyz="0.0 0.0 -1.0"/>
    <parent link="l_hand"/>
    <child link="l_hand_ring_0"/>
    <limit effort="50000.0" lower="0.0" upper="0.3490658402442932" velocity="50000.0"/>
  </joint>
  <link name="l_hand_ring_0">
    <inertial>
      <origin xyz="0.0 0.0 0.0" rpy="0.0 0.0 0.0"/>
      <mass value="0.009999999776482582"/>
      <inertia ixx="0.0010000000474974513" ixy="0.0" ixz="0.0" iyy="0.0010000000474974513" iyz="0.0" izz="0.0010000000474974513"/>
    </inertial>
    <visual name="SM_l_hand_ring_0_visual_0">
      <origin xyz="0.0 0.0 0.0" rpy="0.0 0.0 0.0"/>
      <geometry>
        <mesh filename="file://iCub/meshes/stl/full_LeftRing0.stl" scale="1.0 1.0 1.0"/>
      </geometry>
      <material name="SM_l_hand_ring_0_visual_0_material">
        <color rgba="0.9 0.9 0.9 1.0"/>
      </material>
    </visual>
  </link>
  <joint name="l_hand_ring_1_joint" type="revolute">
    <origin xyz="0.014800000004470348 -0.0017500000540167093 1.0715659546529912e-19" rpy="1.5707963705062866 0.0 0.0"/>
    <axis xyz="0.0 0.0 1.0"/>
    <parent link="l_hand_ring_0"/>
    <child link="l_hand_ring_1"/>
    <limit effort="50000.0" lower="0.0" upper="1.5707963705062866" velocity="50000.0"/>
  </joint>
  <link name="l_hand_ring_1">
    <inertial>
      <origin xyz="0.0 0.0 0.0" rpy="0.0 0.0 0.0"/>
      <mass value="0.009999999776482582"/>
      <inertia ixx="0.0010000000474974513" ixy="0.0" ixz="0.0" iyy="0.0010000000474974513" iyz="0.0" izz="0.0010000000474974513"/>
    </inertial>
    <visual name="SM_l_hand_ring_1_visual_0">
      <origin xyz="0.0 0.0 0.0" rpy="1.5707963705062866 0.0 3.1415927410125732"/>
      <geometry>
        <mesh filename="file://iCub/meshes/stl/full_LeftRing1.stl" scale="1.0 1.0 1.0"/>
      </geometry>
      <material name="SM_l_hand_ring_1_visual_0_material">
        <color rgba="0.9 0.9 0.9 1.0"/>
      </material>
    </visual>
  </link>
  <joint name="l_hand_ring_2_joint" type="revolute">
    <origin xyz="0.02590000070631504 0.0 0.0" rpy="0.0 0.0 0.0"/>
    <axis xyz="0.0 0.0 1.0"/>
    <parent link="l_hand_ring_1"/>
    <child link="l_hand_ring_2"/>
    <limit effort="50000.0" lower="0.0" upper="1.5707963705062866" velocity="50000.0"/>
  </joint>
  <link name="l_hand_ring_2">
    <inertial>
      <origin xyz="0.0 0.0 0.0" rpy="0.0 0.0 0.0"/>
      <mass value="0.009999999776482582"/>
      <inertia ixx="0.0010000000474974513" ixy="0.0" ixz="0.0" iyy="0.0010000000474974513" iyz="0.0" izz="0.0010000000474974513"/>
    </inertial>
    <visual name="SM_l_hand_ring_2_visual_0">
      <origin xyz="0.0 0.0 0.0" rpy="0.0 0.0 3.1415927410125732"/>
      <geometry>
        <mesh filename="file://iCub/meshes/stl/full_LeftRing2.stl" scale="1.0 1.0 1.0"/>
      </geometry>
      <material name="SM_l_hand_ring_2_visual_0_material">
        <color rgba="0.9 0.9 0.9 1.0"/>
      </material>
    </visual>
  </link>
  <joint name="l_hand_ring_3_joint" type="revolute">
    <origin xyz="0.02199999988079071 0.0 0.0" rpy="0.0 0.0 0.0"/>
    <axis xyz="0.0 0.0 1.0"/>
    <parent link="l_hand_ring_2"/>
    <child link="l_hand_ring_3"/>
    <limit effort="50000.0" lower="0.0" upper="1.5707963705062866" velocity="50000.0"/>
  </joint>
  <link name="l_hand_ring_3">
    <inertial>
      <origin xyz="0.0 0.0 0.0" rpy="0.0 0.0 0.0"/>
      <mass value="0.009999999776482582"/>
      <inertia ixx="0.0010000000474974513" ixy="0.0" ixz="0.0" iyy="0.0010000000474974513" iyz="0.0" izz="0.0010000000474974513"/>
    </inertial>
    <visual name="SM_l_hand_ring_3_visual_0">
      <origin xyz="0.0 0.0 0.0" rpy="3.1415927410125732 0.0 3.1415927410125732"/>
      <geometry>
        <mesh filename="file://iCub/meshes/stl/full_LeftRing3.stl" scale="1.0 1.0 1.0"/>
      </geometry>
      <material name="SM_l_hand_ring_3_visual_0_material">
        <color rgba="0.9 0.9 0.9 1.0"/>
      </material>
    </visual>
  </link>
  <joint name="l_hand_ring_tip_joint" type="fixed">
    <origin xyz="0.0168 0.0 0.0" rpy="-1.5707963705062866 0.0 0.0"/>
    <parent link="l_hand_ring_3"/>
    <child link="l_hand_ring_tip"/>
  </joint>
  <link name="l_hand_ring_tip">
    <inertial>
      <origin xyz="0.0 0.0 0.0" rpy="0.0 0.0 0.0"/>
      <mass value="0.0"/>
      <inertia ixx="0.0" ixy="0.0" ixz="0.0" iyy="0.0" iyz="0.0" izz="0.0"/>
    </inertial>
  </link>
  <joint name="l_hand_little_0_joint" type="revolute">
    <origin xyz="0.06362900137901306 0.004443199839442968 -0.010110927745699883" rpy="-1.547965407371521 -2.9872496128082275 3.0537750720977783"/>
    <axis xyz="0.0 0.0 -1.0"/>
    <parent link="l_hand"/>
    <child link="l_hand_little_0"/>
    <limit effort="50000.0" lower="0.0" upper="0.3490658402442932" velocity="50000.0"/>
  </joint>
  <link name="l_hand_little_0">
    <inertial>
      <origin xyz="0.0 0.0 0.0" rpy="0.0 0.0 0.0"/>
      <mass value="0.009999999776482582"/>
      <inertia ixx="0.0010000000474974513" ixy="0.0" ixz="0.0" iyy="0.0010000000474974513" iyz="0.0" izz="0.0010000000474974513"/>
    </inertial>
    <visual name="SM_l_hand_little_0_visual_0">
      <origin xyz="0.0 0.0 0.0" rpy="-3.1415927410125732 -1.5707963705062866 1.5707963705062866"/>
      <geometry>
        <mesh filename="file://iCub/meshes/stl/full_LeftLittle0.stl" scale="1.0 1.0 1.0"/>
      </geometry>
      <material name="SM_l_hand_little_0_visual_0_material">
        <color rgba="0.9 0.9 0.9 1.0"/>
      </material>
    </visual>
  </link>
  <joint name="l_hand_little_1_joint" type="revolute">
    <origin xyz="0.014800000004470348 0.0017500000540167093 -1.0715659546529912e-19" rpy="1.5707963705062866 0.0 0.0"/>
    <axis xyz="0.0 0.0 1.0"/>
    <parent link="l_hand_little_0"/>
    <child link="l_hand_little_1"/>
    <limit effort="50000.0" lower="0.0" upper="1.5707963705062866" velocity="50000.0"/>
  </joint>
  <link name="l_hand_little_1">
    <inertial>
      <origin xyz="0.0 0.0 0.0" rpy="0.0 0.0 0.0"/>
      <mass value="0.009999999776482582"/>
      <inertia ixx="0.0010000000474974513" ixy="0.0" ixz="0.0" iyy="0.0010000000474974513" iyz="0.0" izz="0.0010000000474974513"/>
    </inertial>
    <visual name="SM_l_hand_little_1_visual_0">
      <origin xyz="0.0 0.0 0.0" rpy="0.0 3.1415927410125732 1.5707963705062866"/>
      <geometry>
        <mesh filename="file://iCub/meshes/stl/full_LeftLittle1.stl" scale="1.0 1.0 1.0"/>
      </geometry>
      <material name="SM_l_hand_little_1_visual_0_material">
        <color rgba="0.9 0.9 0.9 1.0"/>
      </material>
    </visual>
  </link>
  <joint name="l_hand_little_2_joint" type="revolute">
    <origin xyz="0.021900000050663948 0.0 0.0" rpy="0.0 0.0 0.0"/>
    <axis xyz="0.0 0.0 1.0"/>
    <parent link="l_hand_little_1"/>
    <child link="l_hand_little_2"/>
    <limit effort="50000.0" lower="0.0" upper="1.5707963705062866" velocity="50000.0"/>
  </joint>
  <link name="l_hand_little_2">
    <inertial>
      <origin xyz="0.0 0.0 0.0" rpy="0.0 0.0 0.0"/>
      <mass value="0.009999999776482582"/>
      <inertia ixx="0.0010000000474974513" ixy="0.0" ixz="0.0" iyy="0.0010000000474974513" iyz="0.0" izz="0.0010000000474974513"/>
    </inertial>
    <visual name="SM_l_hand_little_2_visual_0">
      <origin xyz="0.0 0.0 0.0" rpy="0.0 0.0 3.1415927410125732"/>
      <geometry>
        <mesh filename="file://iCub/meshes/stl/full_LeftLittle2.stl" scale="1.0 1.0 1.0"/>
      </geometry>
      <material name="SM_l_hand_little_2_visual_0_material">
        <color rgba="0.9 0.9 0.9 1.0"/>
      </material>
    </visual>
  </link>
  <joint name="l_hand_little_3_joint" type="revolute">
    <origin xyz="0.01899999938905239 0.0 0.0" rpy="0.0 0.0 0.0"/>
    <axis xyz="0.0 0.0 1.0"/>
    <parent link="l_hand_little_2"/>
    <child link="l_hand_little_3"/>
    <limit effort="50000.0" lower="0.0" upper="1.5707963705062866" velocity="50000.0"/>
  </joint>
  <link name="l_hand_little_3">
    <inertial>
      <origin xyz="0.0 0.0 0.0" rpy="0.0 0.0 0.0"/>
      <mass value="0.009999999776482582"/>
      <inertia ixx="0.0010000000474974513" ixy="0.0" ixz="0.0" iyy="0.0010000000474974513" iyz="0.0" izz="0.0010000000474974513"/>
    </inertial>
    <visual name="SM_l_hand_little_3_visual_0">
      <origin xyz="0.0 0.0 0.0" rpy="3.1415927410125732 0.0 3.1415927410125732"/>
      <geometry>
        <mesh filename="file://iCub/meshes/stl/full_LeftLittle3.stl" scale="1.0 1.0 1.0"/>
      </geometry>
      <material name="SM_l_hand_little_3_visual_0_material">
        <color rgba="0.9 0.9 0.9 1.0"/>
      </material>
    </visual>
  </link>
  <joint name="l_hand_little_tip_joint" type="fixed">
    <origin xyz="0.0168 0.0 0.0" rpy="-1.5707963705062866 0.0 0.0"/>
    <parent link="l_hand_little_3"/>
    <child link="l_hand_little_tip"/>
  </joint>
  <link name="l_hand_little_tip">
    <inertial>
      <origin xyz="0.0 0.0 0.0" rpy="0.0 0.0 0.0"/>
      <mass value="0.0"/>
      <inertia ixx="0.0" ixy="0.0" ixz="0.0" iyy="0.0" iyz="0.0" izz="0.0"/>
    </inertial>
  </link>
  <joint name="base_link_joint" type="fixed">
    <origin xyz="0.0 0.0 0.0" rpy="0.0 0.0 0.0"/>
    <parent link="root_link"/>
    <child link="base_link"/>
  </joint>
  <link name="base_link">
    <inertial>
      <origin xyz="0.0 0.0 0.0" rpy="0.0 0.0 0.0"/>
      <mass value="0.0"/>
      <inertia ixx="0.0" ixy="0.0" ixz="0.0" iyy="0.0" iyz="0.0" izz="0.0"/>
    </inertial>
  </link>
</robot>